Workbook

Sheet Ahorro BBVA
H2: AHORRO MIKEL
L4: TOTAL | N4: TOTAL BBVA | P4: TOTAL BANKINTER | T4: AHORRO ÚLTIMO MES
L5: {=INDEX(I22:I224,MATCH(TRUE,I22:I224>0,0))} -> 141556.83 | N5: {=INDEX(D22:D224,MATCH(TRUE,D22:D224>0,0))} -> 2556.83 | P5: {=INDEX(H22:H224,MATCH(TRUE,H22:H224>0,0))} -> 139000 | T5: {=INDEX(J22:J224,MATCH(TRUE,J22:J224>0,0))} -> 1696.41
A7: Mes | B7: Cuenta | C7: Ahorro | D7: BBVA | E7: Sant | F7: EVO | G7: B100 | H7: Openbank Cajamar | I7: TOTAL | J7: +/-
A8: 46357 | C8: 0 | D8: =IFERROR(IF(ISBLANK(B8)=FALSE,B8,"")+IF(ISBLANK(C8)=FALSE,C8,""),"") | E8: 0 | F8: 0 | G8: 0 | I8: =IFERROR(IF(ISBLANK(D8)=FALSE,D8,"")+IF(ISBLANK(E8)=FALSE,E8,"")+IF(ISBLANK(F8)=FALSE,F8,"")+IF(ISBLANK(G8)=FALSE,G8,"")+IF(ISBLANK(H8)=FALSE,H8,""),"") | J8: =IFERROR(IF(ISBLANK(I8)=FALSE,I8-I9,""),"")
A9: 46327 | C9: 0 | D9: =IFERROR(IF(ISBLANK(B9)=FALSE,B9,"")+IF(ISBLANK(C9)=FALSE,C9,""),"") | E9: 0 | F9: 0 | G9: 0 | I9: =IFERROR(IF(ISBLANK(D9)=FALSE,D9,"")+IF(ISBLANK(E9)=FALSE,E9,"")+IF(ISBLANK(F9)=FALSE,F9,"")+IF(ISBLANK(G9)=FALSE,G9,"")+IF(ISBLANK(H9)=FALSE,H9,""),"") | J9: =IFERROR(IF(ISBLANK(I9)=FALSE,I9-I10,""),"")
A10: 46296 | C10: 0 | D10: =IFERROR(IF(ISBLANK(B10)=FALSE,B10,"")+IF(ISBLANK(C10)=FALSE,C10,""),"") | E10: 0 | F10: 0 | G10: 0 | I10: =IFERROR(IF(ISBLANK(D10)=FALSE,D10,"")+IF(ISBLANK(E10)=FALSE,E10,"")+IF(ISBLANK(F10)=FALSE,F10,"")+IF(ISBLANK(G10)=FALSE,G10,"")+IF(ISBLANK(H10)=FALSE,H10,""),"") | J10: =IFERROR(IF(ISBLANK(I10)=FALSE,I10-I11,""),"")
A11: 46266 | C11: 0 | D11: =IFERROR(IF(ISBLANK(B11)=FALSE,B11,"")+IF(ISBLANK(C11)=FALSE,C11,""),"") | E11: 0 | F11: 0 | G11: 0 | I11: =IFERROR(IF(ISBLANK(D11)=FALSE,D11,"")+IF(ISBLANK(E11)=FALSE,E11,"")+IF(ISBLANK(F11)=FALSE,F11,"")+IF(ISBLANK(G11)=FALSE,G11,"")+IF(ISBLANK(H11)=FALSE,H11,""),"") | J11: =IFERROR(IF(ISBLANK(I11)=FALSE,I11-I12,""),"")
A12: 46235 | C12: 0 | D12: =IFERROR(IF(ISBLANK(B12)=FALSE,B12,"")+IF(ISBLANK(C12)=FALSE,C12,""),"") | E12: 0 | F12: 0 | G12: 0 | I12: =IFERROR(IF(ISBLANK(D12)=FALSE,D12,"")+IF(ISBLANK(E12)=FALSE,E12,"")+IF(ISBLANK(F12)=FALSE,F12,"")+IF(ISBLANK(G12)=FALSE,G12,"")+IF(ISBLANK(H12)=FALSE,H12,""),"") | J12: =IFERROR(IF(ISBLANK(I12)=FALSE,I12-I13,""),"")
A13: 46204 | C13: 0 | D13: =IFERROR(IF(ISBLANK(B13)=FALSE,B13,"")+IF(ISBLANK(C13)=FALSE,C13,""),"") | E13: 0 | F13: 0 | G13: 0 | I13: =IFERROR(IF(ISBLANK(D13)=FALSE,D13,"")+IF(ISBLANK(E13)=FALSE,E13,"")+IF(ISBLANK(F13)=FALSE,F13,"")+IF(ISBLANK(G13)=FALSE,G13,"")+IF(ISBLANK(H13)=FALSE,H13,""),"") | J13: =IFERROR(IF(ISBLANK(I13)=FALSE,I13-I14,""),"")
A14: 46174 | C14: 0 | D14: =IFERROR(IF(ISBLANK(B14)=FALSE,B14,"")+IF(ISBLANK(C14)=FALSE,C14,""),"") | E14: 0 | F14: 0 | G14: 0 | H14: 126000 | I14: =IFERROR(IF(ISBLANK(D14)=FALSE,D14,"")+IF(ISBLANK(E14)=FALSE,E14,"")+IF(ISBLANK(F14)=FALSE,F14,"")+IF(ISBLANK(G14)=FALSE,G14,"")+IF(ISBLANK(H14)=FALSE,H14,""),"") | J14: =IFERROR(IF(ISBLANK(I14)=FALSE,I14-I15,""),"")
A15: 46143 | B15: 946.69 | C15: 0 | D15: =IFERROR(IF(ISBLANK(B15)=FALSE,B15,"")+IF(ISBLANK(C15)=FALSE,C15,""),"") -> 946.69 | E15: 0 | F15: 0 | G15: 0 | H15: =74000+50000 -> 124000 | I15: =IFERROR(IF(ISBLANK(D15)=FALSE,D15,"")+IF(ISBLANK(E15)=FALSE,E15,"")+IF(ISBLANK(F15)=FALSE,F15,"")+IF(ISBLANK(G15)=FALSE,G15,"")+IF(ISBLANK(H15)=FALSE,H15,""),"") -> 124946.69 | J15: =IFERROR(IF(ISBLANK(I15)=FALSE,I15-I16,""),"") -> 1530.18
A16: 46113 | B16: 416.51 | C16: 0 | D16: =IFERROR(IF(ISBLANK(B16)=FALSE,B16,"")+IF(ISBLANK(C16)=FALSE,C16,""),"") -> 416.51 | E16: 0 | F16: 0 | G16: 0 | H16: =50000+73000 -> 123000 | I16: =IFERROR(IF(ISBLANK(D16)=FALSE,D16,"")+IF(ISBLANK(E16)=FALSE,E16,"")+IF(ISBLANK(F16)=FALSE,F16,"")+IF(ISBLANK(G16)=FALSE,G16,"")+IF(ISBLANK(H16)=FALSE,H16,""),"") -> 123416.51 | J16: =IFERROR(IF(ISBLANK(I16)=FALSE,I16-I17,""),"") -> -27681.12
A17: 46082 | B17: 597.63 | C17: 0 | D17: =IFERROR(IF(ISBLANK(B17)=FALSE,B17,"")+IF(ISBLANK(C17)=FALSE,C17,""),"") -> 597.63 | E17: 0 | F17: 0 | G17: 0 | H17: 150500 | I17: =IFERROR(IF(ISBLANK(D17)=FALSE,D17,"")+IF(ISBLANK(E17)=FALSE,E17,"")+IF(ISBLANK(F17)=FALSE,F17,"")+IF(ISBLANK(G17)=FALSE,G17,"")+IF(ISBLANK(H17)=FALSE,H17,""),"") -> 151097.63 | J17: =IFERROR(IF(ISBLANK(I17)=FALSE,I17-I18,""),"") -> 1968.36
A18: 46054 | B18: 629.27 | C18: 0 | D18: =IFERROR(IF(ISBLANK(B18)=FALSE,B18,"")+IF(ISBLANK(C18)=FALSE,C18,""),"") -> 629.27 | E18: 0 | F18: 0 | G18: 0 | H18: 148500 | I18: =IFERROR(IF(ISBLANK(D18)=FALSE,D18,"")+IF(ISBLANK(E18)=FALSE,E18,"")+IF(ISBLANK(F18)=FALSE,F18,"")+IF(ISBLANK(G18)=FALSE,G18,"")+IF(ISBLANK(H18)=FALSE,H18,""),"") -> 149129.27 | J18: =IFERROR(IF(ISBLANK(I18)=FALSE,I18-I19,""),"") -> 1811.7
A19: 46023 | B19: 317.57 | C19: 0 | D19: =IFERROR(IF(ISBLANK(B19)=FALSE,B19,"")+IF(ISBLANK(C19)=FALSE,C19,""),"") -> 317.57 | E19: 0 | F19: 0 | G19: 0 | H19: 147000 | I19: =IFERROR(IF(ISBLANK(D19)=FALSE,D19,"")+IF(ISBLANK(E19)=FALSE,E19,"")+IF(ISBLANK(F19)=FALSE,F19,"")+IF(ISBLANK(G19)=FALSE,G19,"")+IF(ISBLANK(H19)=FALSE,H19,""),"") -> 147317.57 | J19: =IFERROR(IF(ISBLANK(I19)=FALSE,I19-I20,""),"") -> 1844.18
A20: 45992 | B20: 2473.39 | C20: 0 | D20: =IFERROR(IF(ISBLANK(B20)=FALSE,B20,"")+IF(ISBLANK(C20)=FALSE,C20,""),"") -> 2473.39 | E20: 0 | F20: 0 | G20: 0 | H20: 143000 | I20: =IFERROR(IF(ISBLANK(D20)=FALSE,D20,"")+IF(ISBLANK(E20)=FALSE,E20,"")+IF(ISBLANK(F20)=FALSE,F20,"")+IF(ISBLANK(G20)=FALSE,G20,"")+IF(ISBLANK(H20)=FALSE,H20,""),"") -> 145473.39 | J20: =IFERROR(IF(ISBLANK(I20)=FALSE,I20-I21,""),"") -> 2070.13
A21: 45962 | B21: 2403.26 | C21: 0 | D21: =IFERROR(IF(ISBLANK(B21)=FALSE,B21,"")+IF(ISBLANK(C21)=FALSE,C21,""),"") -> 2403.26 | E21: 0 | F21: 0 | G21: 0 | H21: 141000 | I21: =IFERROR(IF(ISBLANK(D21)=FALSE,D21,"")+IF(ISBLANK(E21)=FALSE,E21,"")+IF(ISBLANK(F21)=FALSE,F21,"")+IF(ISBLANK(G21)=FALSE,G21,"")+IF(ISBLANK(H21)=FALSE,H21,""),"") -> 143403.26 | J21: =IFERROR(IF(ISBLANK(I21)=FALSE,I21-I22,""),"") -> 1846.43
A22: 45931 | B22: 2556.83 | C22: 0 | D22: =IFERROR(IF(ISBLANK(B22)=FALSE,B22,"")+IF(ISBLANK(C22)=FALSE,C22,""),"") -> 2556.83 | E22: 0 | F22: 0 | G22: 0 | H22: 139000 | I22: =IFERROR(IF(ISBLANK(D22)=FALSE,D22,"")+IF(ISBLANK(E22)=FALSE,E22,"")+IF(ISBLANK(F22)=FALSE,F22,"")+IF(ISBLANK(G22)=FALSE,G22,"")+IF(ISBLANK(H22)=FALSE,H22,""),"") -> 141556.83 | J22: =IFERROR(IF(ISBLANK(I22)=FALSE,I22-I23,""),"") -> 1696.41
A23: 45901 | B23: 1860.42 | C23: 0 | D23: =IFERROR(IF(ISBLANK(B23)=FALSE,B23,"")+IF(ISBLANK(C23)=FALSE,C23,""),"") -> 1860.42 | E23: 0 | F23: 0 | G23: 0 | H23: 138000 | I23: =IFERROR(IF(ISBLANK(D23)=FALSE,D23,"")+IF(ISBLANK(E23)=FALSE,E23,"")+IF(ISBLANK(F23)=FALSE,F23,"")+IF(ISBLANK(G23)=FALSE,G23,"")+IF(ISBLANK(H23)=FALSE,H23,""),"") -> 139860.42 | J23: =IFERROR(IF(ISBLANK(I23)=FALSE,I23-I24,""),"") -> 1645.17
A24: 45870 | B24: 1215.25 | C24: 0 | D24: =IFERROR(IF(ISBLANK(B24)=FALSE,B24,"")+IF(ISBLANK(C24)=FALSE,C24,""),"") -> 1215.25 | E24: 0 | F24: 0 | G24: 0 | H24: 137000 | I24: =IFERROR(IF(ISBLANK(D24)=FALSE,D24,"")+IF(ISBLANK(E24)=FALSE,E24,"")+IF(ISBLANK(F24)=FALSE,F24,"")+IF(ISBLANK(G24)=FALSE,G24,"")+IF(ISBLANK(H24)=FALSE,H24,""),"") -> 138215.25 | J24: =IFERROR(IF(ISBLANK(I24)=FALSE,I24-I25,""),"") -> -4.6
A25: 45839 | B25: 1219.85 | C25: 0 | D25: =IFERROR(IF(ISBLANK(B25)=FALSE,B25,"")+IF(ISBLANK(C25)=FALSE,C25,""),"") -> 1219.85 | E25: 0 | F25: 0 | G25: 0 | H25: 137000 | I25: =IFERROR(IF(ISBLANK(D25)=FALSE,D25,"")+IF(ISBLANK(E25)=FALSE,E25,"")+IF(ISBLANK(F25)=FALSE,F25,"")+IF(ISBLANK(G25)=FALSE,G25,"")+IF(ISBLANK(H25)=FALSE,H25,""),"") -> 138219.85 | J25: =IFERROR(IF(ISBLANK(I25)=FALSE,I25-I26,""),"") -> -121.89
A26: 45809 | B26: 1341.74 | C26: 0 | D26: =IFERROR(IF(ISBLANK(B26)=FALSE,B26,"")+IF(ISBLANK(C26)=FALSE,C26,""),"") -> 1341.74 | E26: 0 | F26: 0 | G26: 0 | H26: 137000 | I26: =IFERROR(IF(ISBLANK(D26)=FALSE,D26,"")+IF(ISBLANK(E26)=FALSE,E26,"")+IF(ISBLANK(F26)=FALSE,F26,"")+IF(ISBLANK(G26)=FALSE,G26,"")+IF(ISBLANK(H26)=FALSE,H26,""),"") -> 138341.74 | J26: =IFERROR(IF(ISBLANK(I26)=FALSE,I26-I27,""),"") -> 2203.75
A27: 45778 | B27: 637.99 | C27: 0 | D27: =IFERROR(IF(ISBLANK(B27)=FALSE,B27,"")+IF(ISBLANK(C27)=FALSE,C27,""),"") -> 637.99 | E27: 0 | F27: 0 | G27: 0 | H27: 135500 | I27: =IFERROR(IF(ISBLANK(D27)=FALSE,D27,"")+IF(ISBLANK(E27)=FALSE,E27,"")+IF(ISBLANK(F27)=FALSE,F27,"")+IF(ISBLANK(G27)=FALSE,G27,"")+IF(ISBLANK(H27)=FALSE,H27,""),"") -> 136137.99 | J27: =IFERROR(IF(ISBLANK(I27)=FALSE,I27-I28,""),"") -> 1953.17
A28: 45748 | B28: 684.82 | C28: 0 | D28: =IFERROR(IF(ISBLANK(B28)=FALSE,B28,"")+IF(ISBLANK(C28)=FALSE,C28,""),"") -> 684.82 | E28: 0 | F28: 0 | G28: 0 | H28: 133500 | I28: =IFERROR(IF(ISBLANK(D28)=FALSE,D28,"")+IF(ISBLANK(E28)=FALSE,E28,"")+IF(ISBLANK(F28)=FALSE,F28,"")+IF(ISBLANK(G28)=FALSE,G28,"")+IF(ISBLANK(H28)=FALSE,H28,""),"") -> 134184.82 | J28: =IFERROR(IF(ISBLANK(I28)=FALSE,I28-I29,""),"") -> 1834.54
... A101: 43525 | B101: 1493.8 | C101: 39000 | D101: =IFERROR(IF(ISBLANK(B101)=FALSE,B101,"")+IF(ISBLANK(C101)=FALSE,C101,""),"") -> 40493.8 | E101: 0 | F101: 0 | G101: 0 | H101: 0 | I101: =IFERROR(IF(ISBLANK(D101)=FALSE,D101,"")+IF(ISBLANK(E101)=FALSE,E101,"")+IF(ISBLANK(F101)=FALSE,F101,"")+IF(ISBLANK(G101)=FALSE,G101,"")+IF(ISBLANK(H101)=FALSE,H101,""),"") -> 40493.8 | J101: =IFERROR(IF(ISBLANK(I101)=FALSE,I101-I102,""),"") -> 726.64
A102: 43497 | B102: 1767.16 | C102: 38000 | D102: =IFERROR(IF(ISBLANK(B102)=FALSE,B102,"")+IF(ISBLANK(C102)=FALSE,C102,""),"") -> 39767.16 | E102: 0 | F102: 0 | G102: 0 | H102: 0 | I102: =IFERROR(IF(ISBLANK(D102)=FALSE,D102,"")+IF(ISBLANK(E102)=FALSE,E102,"")+IF(ISBLANK(F102)=FALSE,F102,"")+IF(ISBLANK(G102)=FALSE,G102,"")+IF(ISBLANK(H102)=FALSE,H102,""),"") -> 39767.16 | J102: =IFERROR(IF(ISBLANK(I102)=FALSE,I102-I103,""),"") -> 1177.73 | K102: =SUM(J90:J102) -> 12290.77
A103: 43466 | B103: 1589.43 | C103: 37000 | D103: =IFERROR(IF(ISBLANK(B103)=FALSE,B103,"")+IF(ISBLANK(C103)=FALSE,C103,""),"") -> 38589.43 | E103: 0 | F103: 0 | G103: 0 | H103: 0 | I103: =IFERROR(IF(ISBLANK(D103)=FALSE,D103,"")+IF(ISBLANK(E103)=FALSE,E103,"")+IF(ISBLANK(F103)=FALSE,F103,"")+IF(ISBLANK(G103)=FALSE,G103,"")+IF(ISBLANK(H103)=FALSE,H103,""),"") -> 38589.43 | J103: =IFERROR(IF(ISBLANK(I103)=FALSE,I103-I104,""),"") -> 797.01
A104: 43435 | B104: 1792.42 | C104: 36000 | D104: =IFERROR(IF(ISBLANK(B104)=FALSE,B104,"")+IF(ISBLANK(C104)=FALSE,C104,""),"") -> 37792.42 | E104: 0 | F104: 0 | G104: 0 | H104: 0 | I104: =IFERROR(IF(ISBLANK(D104)=FALSE,D104,"")+IF(ISBLANK(E104)=FALSE,E104,"")+IF(ISBLANK(F104)=FALSE,F104,"")+IF(ISBLANK(G104)=FALSE,G104,"")+IF(ISBLANK(H104)=FALSE,H104,""),"") -> 37792.42 | J104: =IFERROR(IF(ISBLANK(I104)=FALSE,I104-I105,""),"") -> 1017.59
A105: 43405 | B105: 1774.83 | C105: 35000 | D105: =IFERROR(IF(ISBLANK(B105)=FALSE,B105,"")+IF(ISBLANK(C105)=FALSE,C105,""),"") -> 36774.83 | E105: 0 | F105: 0 | G105: 0 | H105: 0 | I105: =IFERROR(IF(ISBLANK(D105)=FALSE,D105,"")+IF(ISBLANK(E105)=FALSE,E105,"")+IF(ISBLANK(F105)=FALSE,F105,"")+IF(ISBLANK(G105)=FALSE,G105,"")+IF(ISBLANK(H105)=FALSE,H105,""),"") -> 36774.83 | J105: =IFERROR(IF(ISBLANK(I105)=FALSE,I105-I106,""),"") -> 930.31
A106: 43374 | B106: 1844.52 | C106: 34000 | D106: =IFERROR(IF(ISBLANK(B106)=FALSE,B106,"")+IF(ISBLANK(C106)=FALSE,C106,""),"") -> 35844.52 | E106: 0 | F106: 0 | G106: 0 | H106: 0 | I106: =IFERROR(IF(ISBLANK(D106)=FALSE,D106,"")+IF(ISBLANK(E106)=FALSE,E106,"")+IF(ISBLANK(F106)=FALSE,F106,"")+IF(ISBLANK(G106)=FALSE,G106,"")+IF(ISBLANK(H106)=FALSE,H106,""),"") -> 35844.52 | J106: =IFERROR(IF(ISBLANK(I106)=FALSE,I106-I107,""),"") -> 1360.79
A107: 43344 | B107: 2483.73 | C107: 32000 | D107: =IFERROR(IF(ISBLANK(B107)=FALSE,B107,"")+IF(ISBLANK(C107)=FALSE,C107,""),"") -> 34483.73 | E107: 0 | F107: 0 | G107: 0 | H107: 0 | I107: =IFERROR(IF(ISBLANK(D107)=FALSE,D107,"")+IF(ISBLANK(E107)=FALSE,E107,"")+IF(ISBLANK(F107)=FALSE,F107,"")+IF(ISBLANK(G107)=FALSE,G107,"")+IF(ISBLANK(H107)=FALSE,H107,""),"") -> 34483.73 | J107: =IFERROR(IF(ISBLANK(I107)=FALSE,I107-I108,""),"") -> 705.07
A108: 43313 | B108: 1778.66 | C108: 32000 | D108: =IFERROR(IF(ISBLANK(B108)=FALSE,B108,"")+IF(ISBLANK(C108)=FALSE,C108,""),"") -> 33778.66 | E108: 0 | F108: 0 | G108: 0 | H108: 0 | I108: =IFERROR(IF(ISBLANK(D108)=FALSE,D108,"")+IF(ISBLANK(E108)=FALSE,E108,"")+IF(ISBLANK(F108)=FALSE,F108,"")+IF(ISBLANK(G108)=FALSE,G108,"")+IF(ISBLANK(H108)=FALSE,H108,""),"") -> 33778.66 | J108: =IFERROR(IF(ISBLANK(I108)=FALSE,I108-I109,""),"") -> 966.65
A109: 43282 | B109: 1812.01 | C109: 31000 | D109: =IFERROR(IF(ISBLANK(B109)=FALSE,B109,"")+IF(ISBLANK(C109)=FALSE,C109,""),"") -> 32812.01 | E109: 0 | F109: 0 | G109: 0 | H109: 0 | I109: =IFERROR(IF(ISBLANK(D109)=FALSE,D109,"")+IF(ISBLANK(E109)=FALSE,E109,"")+IF(ISBLANK(F109)=FALSE,F109,"")+IF(ISBLANK(G109)=FALSE,G109,"")+IF(ISBLANK(H109)=FALSE,H109,""),"") -> 32812.01 | J109: =IFERROR(IF(ISBLANK(I109)=FALSE,I109-I110,""),"") -> 541.72
A110: 43252 | B110: 1270.29 | C110: 31000 | D110: =IFERROR(IF(ISBLANK(B110)=FALSE,B110,"")+IF(ISBLANK(C110)=FALSE,C110,""),"") -> 32270.29 | E110: 0 | F110: 0 | G110: 0 | H110: 0 | I110: =IFERROR(IF(ISBLANK(D110)=FALSE,D110,"")+IF(ISBLANK(E110)=FALSE,E110,"")+IF(ISBLANK(F110)=FALSE,F110,"")+IF(ISBLANK(G110)=FALSE,G110,"")+IF(ISBLANK(H110)=FALSE,H110,""),"") -> 32270.29 | J110: =IFERROR(IF(ISBLANK(I110)=FALSE,I110-I111,""),"") -> 2.46
A111: 43221 | B111: 1267.83 | C111: 31000 | D111: =IFERROR(IF(ISBLANK(B111)=FALSE,B111,"")+IF(ISBLANK(C111)=FALSE,C111,""),"") -> 32267.83 | E111: 0 | F111: 0 | G111: 0 | H111: 0 | I111: =IFERROR(IF(ISBLANK(D111)=FALSE,D111,"")+IF(ISBLANK(E111)=FALSE,E111,"")+IF(ISBLANK(F111)=FALSE,F111,"")+IF(ISBLANK(G111)=FALSE,G111,"")+IF(ISBLANK(H111)=FALSE,H111,""),"") -> 32267.83 | J111: =IFERROR(IF(ISBLANK(I111)=FALSE,I111-I112,""),"") -> -268.61
A112: 43191 | B112: 1536.44 | C112: 31000 | D112: =IFERROR(IF(ISBLANK(B112)=FALSE,B112,"")+IF(ISBLANK(C112)=FALSE,C112,""),"") -> 32536.44 | E112: 0 | F112: 0 | G112: 0 | H112: 0 | I112: =IFERROR(IF(ISBLANK(D112)=FALSE,D112,"")+IF(ISBLANK(E112)=FALSE,E112,"")+IF(ISBLANK(F112)=FALSE,F112,"")+IF(ISBLANK(G112)=FALSE,G112,"")+IF(ISBLANK(H112)=FALSE,H112,""),"") -> 32536.44 | J112: =IFERROR(IF(ISBLANK(I112)=FALSE,I112-I113,""),"") -> 144.23
A113: 43160 | B113: 1392.21 | C113: 31000 | D113: =IFERROR(IF(ISBLANK(B113)=FALSE,B113,"")+IF(ISBLANK(C113)=FALSE,C113,""),"") -> 32392.21 | E113: 0 | F113: 0 | G113: 0 | H113: 0 | I113: =IFERROR(IF(ISBLANK(D113)=FALSE,D113,"")+IF(ISBLANK(E113)=FALSE,E113,"")+IF(ISBLANK(F113)=FALSE,F113,"")+IF(ISBLANK(G113)=FALSE,G113,"")+IF(ISBLANK(H113)=FALSE,H113,""),"") -> 32392.21 | J113: =IFERROR(IF(ISBLANK(I113)=FALSE,I113-I114,""),"") -> 24.63
A114: 43132 | B114: 1367.58 | C114: 31000 | D114: =IFERROR(IF(ISBLANK(B114)=FALSE,B114,"")+IF(ISBLANK(C114)=FALSE,C114,""),"") -> 32367.58 | E114: 0 | F114: 0 | G114: 0 | H114: 0 | I114: =IFERROR(IF(ISBLANK(D114)=FALSE,D114,"")+IF(ISBLANK(E114)=FALSE,E114,"")+IF(ISBLANK(F114)=FALSE,F114,"")+IF(ISBLANK(G114)=FALSE,G114,"")+IF(ISBLANK(H114)=FALSE,H114,""),"") -> 32367.58 | J114: =IFERROR(IF(ISBLANK(I114)=FALSE,I114-I115,""),"") -> 6.34 | K114: =SUM(J103:J114) -> 6228.19
A115: 43101 | B115: 1361.24 | C115: 31000 | D115: =IFERROR(IF(ISBLANK(B115)=FALSE,B115,"")+IF(ISBLANK(C115)=FALSE,C115,""),"") -> 32361.24 | E115: 0 | F115: 0 | G115: 0 | H115: 0 | I115: =IFERROR(IF(ISBLANK(D115)=FALSE,D115,"")+IF(ISBLANK(E115)=FALSE,E115,"")+IF(ISBLANK(F115)=FALSE,F115,"")+IF(ISBLANK(G115)=FALSE,G115,"")+IF(ISBLANK(H115)=FALSE,H115,""),"") -> 32361.24 | J115: =IFERROR(IF(ISBLANK(I115)=FALSE,I115-I116,""),"") -> 709.29
...

Sheet 25 26 Vadillo
C2: Vadillo Asesores
C5: TOTAL | D5: =+J45+J20 -> 13955.07
D7: Bruto | E7: SS | F7: Desemp | H7: IRPF | I7: Sueldo | J7: Ingresado | K7: Diferencia | Q7: 2026
B8: 2026 | C8: 45658 | D8: 2166.6667 | E8: =(D8+G8)*4.85/100 -> 105.08333 | F8: =(D8+G8)*0.0165 -> 35.75 | H8: =D8*$N$14 -> 281.66667 | I8: =D8-E8-H8-F8 -> 1744.1667 | J8: 1744.17 | K8: =IF(ISBLANK(J8)," ",IF(ABS(J8-I8)<0.01,"Correcto ",IF(J8-I8<0,"Faltan","Sobran"))) -> Correcto | L8: =IF(ISBLANK(J8)," ",IF(ABS(J8-I8)<0.01," ",J8-I8)) | R8: L | S8: M | T8: X | U8: J | V8: V | W8: S | X8: D | Y8: L | Z8: M | AA8: X | AB8: J | AC8: V | AD8: S | AE8: D | AF8: L | AG8: M | AH8: X | AI8: J | AJ8: V | AK8: S | AL8: D | AM8: L | AN8: M | AO8: X | AP8: J | AQ8: V | AR8: S | AS8: D | AT8: L | AU8: M | AV8: X | AW8: J | AX8: V | AY8: S | AZ8: D | BA8: L | BB8: M
C9: 45689 | D9: 2166.6667 | E9: =(D9+G9)*4.85/100 -> 105.08333 | F9: =(D9+G9)*0.0165 -> 35.75 | H9: =D9*$N$14 -> 281.66667 | I9: =D9-E9-H9-F9 -> 1744.1667 | J9: 1744.17 | K9: =IF(ISBLANK(J9)," ",IF(ABS(J9-I9)<0.01,"Correcto ",IF(J9-I9<0,"Faltan","Sobran"))) -> Correcto | L9: =IF(ISBLANK(J9)," ",IF(ABS(J9-I9)<0.01," ",J9-I9)) | Q9: ENE | U9: 1 | V9: 2 | W9: 3 | X9: 4 | Y9: 5 | Z9: 6 | AA9: 7 | AB9: 8 | AC9: 9 | AD9: 10 | AE9: 11 | AF9: 12 | AG9: 13 | AH9: 14 | AI9: 15 | AJ9: 16 | AK9: 17 | AL9: 18 | AM9: 19 | AN9: 20 | AO9: 21 | AP9: 22 | AQ9: 23 | AR9: 24 | AS9: 25 | AT9: 26 | AU9: 27 | AV9: 28 | AW9: 29 | AX9: 30 | AY9: 31
C10: 45717 | D10: 2166.6667 | E10: =(D10+G10)*4.85/100 -> 105.08333 | F10: =(D10+G10)*0.0165 -> 35.75 | H10: =D10*$N$14 -> 281.66667 | I10: =D10-E10-H10-F10 -> 1744.1667 | J10: 1744.17 | K10: =IF(ISBLANK(J10)," ",IF(ABS(J10-I10)<0.01,"Correcto ",IF(J10-I10<0,"Faltan","Sobran"))) -> Correcto | L10: =IF(ISBLANK(J10)," ",IF(ABS(J10-I10)<0.01," ",J10-I10)) | Q10: FEB | X10: 1 | Y10: 2 | Z10: 3 | AA10: 4 | AB10: 5 | AC10: 6 | AD10: 7 | AE10: 8 | AF10: 9 | AG10: 10 | AH10: 11 | AI10: 12 | AJ10: 13 | AK10: 14 | AL10: 15 | AM10: 16 | AN10: 17 | AO10: 18 | AP10: 19 | AQ10: 20 | AR10: 21 | AS10: 22 | AT10: 23 | AU10: 24 | AV10: 25 | AW10: 26 | AX10: 27 | AY10: 28
C11: 45748 | D11: 2166.6667 | E11: =(D11+G11)*4.85/100 -> 105.08333 | F11: =(D11+G11)*0.0165 -> 35.75 | H11: =D11*$N$14 -> 281.66667 | I11: =D11-E11-H11-F11 -> 1744.1667 | J11: 1744.17 | K11: =IF(ISBLANK(J11)," ",IF(ABS(J11-I11)<0.01,"Correcto ",IF(J11-I11<0,"Faltan","Sobran"))) -> Correcto | L11: =IF(ISBLANK(J11)," ",IF(ABS(J11-I11)<0.01," ",J11-I11)) | N11: Rend trabajo 2025 | O11: =SUM(D8:D19) -> 25999.996 | Q11: MAR | X11: 1 | Y11: 2 | Z11: 3 | AA11: 4 | AB11: 5 | AC11: 6 | AD11: 7 | AE11: 8 | AF11: 9 | AG11: 10 | AH11: 11 | AI11: 12 | AJ11: 13 | AK11: 14 | AL11: 15 | AM11: 16 | AN11: 17 | AO11: 18 | AP11: 19 | AQ11: 20 | AR11: 21 | AS11: 22 | AT11: 23 | AU11: 24 | AV11: 25 | AW11: 26 | AX11: 27 | AY11: 28 | AZ11: 29 | BA11: 30 | BB11: 31
C12: 45778 | D12: 2166.6667 | E12: =(D12+G12)*4.85/100 -> 105.08333 | F12: =(D12+G12)*0.0165 -> 35.75 | H12: =D12*$N$14 -> 281.66667 | I12: =D12-E12-H12-F12-G12 -> 1744.1667 | K12: =IF(ISBLANK(J12)," ",IF(ABS(J12-I12)<0.01,"Correcto ",IF(J12-I12<0,"Faltan","Sobran"))) | L12: =IF(ISBLANK(J12)," ",IF(ABS(J12-I12)<0.01," ",J12-I12)) | N12: Gastos Deducibles SS | O12: =SUM(E8:F19) -> 1689.9998 | Q12: ABR | T12: 1 | U12: 2 | V12: 3 | W12: 4 | X12: 5 | Y12: 6 | Z12: 7 | AA12: 8 | AB12: 9 | AC12: 10 | AD12: 11 | AE12: 12 | AF12: 13 | AG12: 14 | AH12: 15 | AI12: 16 | AJ12: 17 | AK12: 18 | AL12: 19 | AM12: 20 | AN12: 21 | AO12: 22 | AP12: 23 | AQ12: 24 | AR12: 25 | AS12: 26 | AT12: 27 | AU12: 28 | AV12: 29 | AW12: 30
C13: 45809 | D13: 2166.6667 | E13: =(D13+G13)*4.85/100 -> 105.08333 | F13: =(D13+G13)*0.0165 -> 35.75 | H13: =D13*$N$14 -> 281.66667 | I13: =D13-E13-H13-F13-G13 -> 1744.1667 | K13: =IF(ISBLANK(J13)," ",IF(ABS(J13-I13)<0.01,"Correcto ",IF(J13-I13<0,"Faltan","Sobran"))) | L13: =IF(ISBLANK(J13)," ",IF(ABS(J13-I13)<0.01," ",J13-I13)) | N13: IRPF | O13: =SUM(H8:H19) -> 3379.9995 | Q13: MAY | V13: 1 | W13: 2 | X13: 3 | Y13: 4 | Z13: 5 | AA13: 6 | AB13: 7 | AC13: 8 | AD13: 9 | AE13: 10 | AF13: 11 | AG13: 12 | AH13: 13 | AI13: 14 | AJ13: 15 | AK13: 16 | AL13: 17 | AM13: 18 | AN13: 19 | AO13: 20 | AP13: 21 | AQ13: 22 | AR13: 23 | AS13: 24 | AT13: 25 | AU13: 26 | AV13: 27 | AW13: 28 | AX13: 29 | AY13: 30 | AZ13: 31
C14: 45839 | D14: 2166.6667 | E14: =(D14+G14)*4.85/100 -> 105.08333 | F14: =(D14+G14)*0.0165 -> 35.75 | H14: =D14*$N$14 -> 281.66667 | I14: =D14-E14-H14-F14-G14 -> 1744.1667 | K14: =IF(ISBLANK(J14)," ",IF(ABS(J14-I14)<0.01,"Correcto ",IF(J14-I14<0,"Faltan","Sobran"))) | L14: =IF(ISBLANK(J14)," ",IF(ABS(J14-I14)<0.01," ",J14-I14)) | N14: 0.13 | Q14: JUN | R14: 1 | S14: 2 | T14: 3 | U14: 4 | V14: 5 | W14: 6 | X14: 7 | Y14: 8 | Z14: 9 | AA14: 10 | AB14: 11 | AC14: 12 | AD14: 13 | AE14: 14 | AF14: 15 | AG14: 16 | AH14: 17 | AI14: 18 | AJ14: 19 | AK14: 20 | AL14: 21 | AM14: 22 | AN14: 23 | AO14: 24 | AP14: 25 | AQ14: 26 | AR14: 27 | AS14: 28 | AT14: 29 | AU14: 30
C15: 45870 | D15: 2166.6667 | E15: =(D15+G15)*4.85/100 -> 105.08333 | F15: =(D15+G15)*0.0165 -> 35.75 | H15: =D15*$N$14 -> 281.66667 | I15: =D15-E15-H15-F15-G15 -> 1744.1667 | K15: =IF(ISBLANK(J15)," ",IF(ABS(J15-I15)<0.01,"Correcto ",IF(J15-I15<0,"Faltan","Sobran"))) | L15: =IF(ISBLANK(J15)," ",IF(ABS(J15-I15)<0.01," ",J15-I15)) | Q15: JUL | T15: 1 | U15: 2 | V15: 3 | W15: 4 | X15: 5 | Y15: 6 | Z15: 7 | AA15: 8 | AB15: 9 | AC15: 10 | AD15: 11 | AE15: 12 | AF15: 13 | AG15: 14 | AH15: 15 | AI15: 16 | AJ15: 17 | AK15: 18 | AL15: 19 | AM15: 20 | AN15: 21 | AO15: 22 | AP15: 23 | AQ15: 24 | AR15: 25 | AS15: 26 | AT15: 27 | AU15: 28 | AV15: 29 | AW15: 30 | AX15: 31
C16: 45901 | D16: =1857.14285714286+309.52 -> 2166.6629 | E16: =(D16+G16)*4.85/100 -> 105.08315 | F16: =(D16+G16)*0.0165 -> 35.749937 | H16: =D16*$N$14 -> 281.66617 | I16: =D16-E16-H16-F16-G16 -> 1744.1636 | K16: =IF(ISBLANK(J16)," ",IF(ABS(J16-I16)<0.01,"Correcto ",IF(J16-I16<0,"Faltan","Sobran"))) | L16: =IF(ISBLANK(J16)," ",IF(ABS(J16-I16)<0.01," ",J16-I16)) | N16: VACACIONES | O16: 22+1 | Q16: AGO | W16: 1 | X16: 2 | Y16: 3 | Z16: 4 | AA16: 5 | AB16: 6 | AC16: 7 | AD16: 8 | AE16: 9 | AF16: 10 | AG16: 11 | AH16: 12 | AI16: 13 | AJ16: 14 | AK16: 15 | AL16: 16 | AM16: 17 | AN16: 18 | AO16: 19 | AP16: 20 | AQ16: 21 | AR16: 22 | AS16: 23 | AT16: 24 | AU16: 25 | AV16: 26 | AW16: 27 | AX16: 28 | AY16: 29 | AZ16: 30 | BA16: 31
C17: 45931 | D17: 2166.6667 | E17: =(D17+G17)*4.85/100 -> 105.08333 | F17: =(D17+G17)*0.0165 -> 35.75 | H17: =D17*$N$14 -> 281.66667 | I17: =D17-E17-H17-F17-G17 -> 1744.1667 | K17: =IF(ISBLANK(J17)," ",IF(ABS(J17-I17)<0.01,"Correcto ",IF(J17-I17<0,"Faltan","Sobran"))) | L17: =IF(ISBLANK(J17)," ",IF(ABS(J17-I17)<0.01," ",J17-I17)) | N17: 29jun-2jul | O17: 4 | Q17: SEP | S17: 1 | T17: 2 | U17: 3 | V17: 4 | W17: 5 | X17: 6 | Y17: 7 | Z17: 8 | AA17: 9 | AB17: 10 | AC17: 11 | AD17: 12 | AE17: 13 | AF17: 14 | AG17: 15 | AH17: 16 | AI17: 17 | AJ17: 18 | AK17: 19 | AL17: 20 | AM17: 21 | AN17: 22 | AO17: 23 | AP17: 24 | AQ17: 25 | AR17: 26 | AS17: 27 | AT17: 28 | AU17: 29 | AV17: 30
C18: 45962 | D18: 2166.6667 | E18: =(D18+G18)*4.85/100 -> 105.08333 | F18: =(D18+G18)*0.0165 -> 35.75 | H18: =D18*$N$14 -> 281.66667 | I18: =D18-E18-H18-F18-G18 -> 1744.1667 | K18: =IF(ISBLANK(J18)," ",IF(ABS(J18-I18)<0.01,"Correcto ",IF(J18-I18<0,"Faltan","Sobran"))) | L18: =IF(ISBLANK(J18)," ",IF(ABS(J18-I18)<0.01," ",J18-I18)) | N18: 6-21 ago | O18: 12 | Q18: OCT | U18: 1 | V18: 2 | W18: 3 | X18: 4 | Y18: 5 | Z18: 6 | AA18: 7 | AB18: 8 | AC18: 9 | AD18: 10 | AE18: 11 | AF18: 12 | AG18: 13 | AH18: 14 | AI18: 15 | AJ18: 16 | AK18: 17 | AL18: 18 | AM18: 19 | AN18: 20 | AO18: 21 | AP18: 22 | AQ18: 23 | AR18: 24 | AS18: 25 | AT18: 26 | AU18: 27 | AV18: 28 | AW18: 29 | AX18: 30 | AY18: 31
C19: 45992 | D19: 2166.6667 | E19: =(D19+G19)*4.85/100 -> 105.08333 | F19: =(D19+G19)*0.0165 -> 35.75 | H19: =D19*$N$14 -> 281.66667 | I19: =D19-E19-H19-F19-G19 -> 1744.1667 | K19: =IF(ISBLANK(J19)," ",IF(ABS(J19-I19)<0.01,"Correcto ",IF(J19-I19<0,"Faltan","Sobran"))) | L19: =IF(ISBLANK(J19)," ",IF(ABS(J19-I19)<0.01," ",J19-I19)) | N19: 14 21 septiembre | O19: 6 | Q19: NOV | X19: 1 | Y19: 2 | Z19: 3 | AA19: 4 | AB19: 5 | AC19: 6 | AD19: 7 | AE19: 8 | AF19: 9 | AG19: 10 | AH19: 11 | AI19: 12 | AJ19: 13 | AK19: 14 | AL19: 15 | AM19: 16 | AN19: 17 | AO19: 18 | AP19: 19 | AQ19: 20 | AR19: 21 | AS19: 22 | AT19: 23 | AU19: 24 | AV19: 25 | AW19: 26 | AX19: 27 | AY19: 28 | AZ19: 29 | BA19: 30
D20: =SUM(D8:D19) -> 25999.996 | E20: =SUM(E8:E19) -> 1260.9998 | F20: =SUM(F8:F19) -> 428.99994 | G20: =SUM(G8:G19) -> 0 | H20: =SUM(H8:H19) -> 3379.9995 | I20: =SUM(I8:I19) -> 20929.997 | J20: =SUM(J8:J19) -> 6976.68 | N20: Disfrutadas | O20: =SUM(O17:O19) -> 22 | Q20: DIC | S20: 1 | T20: 2 | U20: 3 | V20: 4 | W20: 5 | X20: 6 | Y20: 7 | Z20: 8 | AA20: 9 | AB20: 10 | AC20: 11 | AD20: 12 | AE20: 13 | AF20: 14 | AG20: 15 | AH20: 16 | AI20: 17 | AJ20: 18 | AK20: 19 | AL20: 20 | AM20: 21 | AN20: 22 | AO20: 23 | AP20: 24 | AQ20: 25 | AR20: 26 | AS20: 27 | AT20: 28 | AU20: 29 | AV20: 30 | AW20: 31
D21: =D20-E20-H20-F20-G20 -> 20929.997 | N21: =+IF(O20<O15,"Por coger",IF(O20>O15,"Del año que viene"," ")) -> Del año que viene
D29: Bruto | E29: SS | F29: Desemp | H29: IRPF | I29: Sueldo | J29: Ingresado | K29: Diferencia | Q29: 2025
B30: 2025 | C30: 45658 | I30: =D30-E30-H30-F30 -> 0 | K30: =IF(ISBLANK(J30)," ",IF(ABS(J30-I30)<0.01,"Correcto ",IF(J30-I30<0,"Faltan","Sobran"))) | L30: =IF(ISBLANK(J30)," ",IF(ABS(J30-I30)<0.01," ",J30-I30)) | R30: L | S30: M | T30: X | U30: J | V30: V | W30: S | X30: D | Y30: L | Z30: M | AA30: X | AB30: J | AC30: V | AD30: S | AE30: D | AF30: L | AG30: M | AH30: X | AI30: J | AJ30: V | AK30: S | AL30: D | AM30: L | AN30: M | AO30: X | AP30: J | AQ30: V | AR30: S | AS30: D | AT30: L | AU30: M | AV30: X | AW30: J | AX30: V | AY30: S | AZ30: D | BA30: L | BB30: M
C31: 45689 | I31: =D31-E31-H31-F31 -> 0 | K31: =IF(ISBLANK(J31)," ",IF(ABS(J31-I31)<0.01,"Correcto ",IF(J31-I31<0,"Faltan","Sobran"))) | L31: =IF(ISBLANK(J31)," ",IF(ABS(J31-I31)<0.01," ",J31-I31)) | Q31: SEP | R31: 1 | S31: 2 | T31: 3 | U31: 4 | V31: 5 | W31: 6 | X31: 7 | Y31: 8 | Z31: 9 | AA31: 10 | AB31: 11 | AC31: 12 | AD31: 13 | AE31: 14 | AF31: 15 | AG31: 16 | AH31: 17 | AI31: 18 | AJ31: 19 | AK31: 20 | AL31: 21 | AM31: 22 | AN31: 23 | AO31: 24 | AP31: 25 | AQ31: 26 | AR31: 27 | AS31: 28 | AT31: 29 | AU31: 30
C32: 45717 | I32: =D32-E32-H32-F32 -> 0 | K32: =IF(ISBLANK(J32)," ",IF(ABS(J32-I32)<0.01,"Correcto ",IF(J32-I32<0,"Faltan","Sobran"))) | L32: =IF(ISBLANK(J32)," ",IF(ABS(J32-I32)<0.01," ",J32-I32)) | Q32: OCT | T32: 1 | U32: 2 | V32: 3 | W32: 4 | X32: 5 | Y32: 6 | Z32: 7 | AA32: 8 | AB32: 9 | AC32: 10 | AD32: 11 | AE32: 12 | AF32: 13 | AG32: 14 | AH32: 15 | AI32: 16 | AJ32: 17 | AK32: 18 | AL32: 19 | AM32: 20 | AN32: 21 | AO32: 22 | AP32: 23 | AQ32: 24 | AR32: 25 | AS32: 26 | AT32: 27 | AU32: 28 | AV32: 29 | AW32: 30 | AX32: 31
C33: 45748 | I33: =D33-E33-H33-F33 -> 0 | K33: =IF(ISBLANK(J33)," ",IF(ABS(J33-I33)<0.01,"Correcto ",IF(J33-I33<0,"Faltan","Sobran"))) | L33: =IF(ISBLANK(J33)," ",IF(ABS(J33-I33)<0.01," ",J33-I33)) | N33: Rend trabajo 2025 | O33: =SUM(D30:D43) -> 8666.6629 | Q33: NOV | W33: 1 | X33: 2 | Y33: 3 | Z33: 4 | AA33: 5 | AB33: 6 | AC33: 7 | AD33: 8 | AE33: 9 | AF33: 10 | AG33: 11 | AH33: 12 | AI33: 13 | AJ33: 14 | AK33: 15 | AL33: 16 | AM33: 17 | AN33: 18 | AO33: 19 | AP33: 20 | AQ33: 21 | AR33: 22 | AS33: 23 | AT33: 24 | AU33: 25 | AV33: 26 | AW33: 27 | AX33: 28 | AY33: 29 | AZ33: 30
C34: 45778 | I34: =D34-E34-H34-F34-G34 -> 0 | K34: =IF(ISBLANK(J34)," ",IF(ABS(J34-I34)<0.01,"Correcto ",IF(J34-I34<0,"Faltan","Sobran"))) | L34: =IF(ISBLANK(J34)," ",IF(ABS(J34-I34)<0.01," ",J34-I34)) | N34: Gastos Deducibles SS | O34: =SUM(E30:F43) -> 561.59975 | Q34: DIC | R34: 1 | S34: 2 | T34: 3 | U34: 4 | V34: 5 | W34: 6 | X34: 7 | Y34: 8 | Z34: 9 | AA34: 10 | AB34: 11 | AC34: 12 | AD34: 13 | AE34: 14 | AF34: 15 | AG34: 16 | AH34: 17 | AI34: 18 | AJ34: 19 | AK34: 20 | AL34: 21 | AM34: 22 | AN34: 23 | AO34: 24 | AP34: 25 | AQ34: 26 | AR34: 27 | AS34: 28 | AT34: 29 | AU34: 30 | AV34: 31
C35: 45809 | I35: =D35-E35-H35-F35-G35 -> 0 | K35: =IF(ISBLANK(J35)," ",IF(ABS(J35-I35)<0.01,"Correcto ",IF(J35-I35<0,"Faltan","Sobran"))) | L35: =IF(ISBLANK(J35)," ",IF(ABS(J35-I35)<0.01," ",J35-I35)) | N35: IRPF | O35: =SUM(H30:H43) -> 1126.6662
I36: =D36-E36-H36-F36-G36 -> 0 | K36: =IF(ISBLANK(J36)," ",IF(ABS(J36-I36)<0.01,"Correcto ",IF(J36-I36<0,"Faltan","Sobran"))) | L36: =IF(ISBLANK(J36)," ",IF(ABS(J36-I36)<0.01," ",J36-I36)) | N36: 0.13 | R36: Del Octubre a Mayo de 8:30-14:30 - 15:00-17:30
C37: 45839 | I37: =D37-E37-H37-F37-G37 -> 0 | K37: =IF(ISBLANK(J37)," ",IF(ABS(J37-I37)<0.01,"Correcto ",IF(J37-I37<0,"Faltan","Sobran"))) | L37: =IF(ISBLANK(J37)," ",IF(ABS(J37-I37)<0.01," ",J37-I37)) | R37: De Junio a Septiembre de 8 a 15
C38: 45870 | I38: =D38-E38-H38-F38-G38 -> 0 | K38: =IF(ISBLANK(J38)," ",IF(ABS(J38-I38)<0.01,"Correcto ",IF(J38-I38<0,"Faltan","Sobran"))) | L38: =IF(ISBLANK(J38)," ",IF(ABS(J38-I38)<0.01," ",J38-I38))
C39: 45901 | D39: =1857.14285714286+309.52 -> 2166.6629 | E39: =(D39+G39)*0.0483 -> 104.64982 | F39: =(D39+G39)*0.0165 -> 35.749937 | H39: =D39*$N$36 -> 281.66617 | I39: =D39-E39-H39-F39-G39 -> 1744.5969 | J39: 1744.59 | K39: =IF(ISBLANK(J39)," ",IF(ABS(J39-I39)<0.01,"Correcto ",IF(J39-I39<0,"Faltan","Sobran"))) -> Correcto | L39: =IF(ISBLANK(J39)," ",IF(ABS(J39-I39)<0.01," ",J39-I39)) | N39: VACACIONES | O39: =22/12*4 -> 7.3333333
C40: 45931 | D40: 2166.6667 | E40: =(D40+G40)*0.0483 -> 104.65 | F40: =(D40+G40)*0.0165 -> 35.75 | H40: =D40*$N$36 -> 281.66667 | I40: =D40-E40-H40-F40-G40 -> 1744.6 | J40: 1744.6 | K40: =IF(ISBLANK(J40)," ",IF(ABS(J40-I40)<0.01,"Correcto ",IF(J40-I40<0,"Faltan","Sobran"))) -> Correcto | L40: =IF(ISBLANK(J40)," ",IF(ABS(J40-I40)<0.01," ",J40-I40)) | N40: 9 12 diciembre | O40: 4
C41: 45962 | D41: 2166.6667 | E41: =(D41+G41)*0.0483 -> 104.65 | F41: =(D41+G41)*0.0165 -> 35.75 | H41: =D41*$N$36 -> 281.66667 | I41: =D41-E41-H41-F41-G41 -> 1744.6 | J41: 1744.6 | K41: =IF(ISBLANK(J41)," ",IF(ABS(J41-I41)<0.01,"Correcto ",IF(J41-I41<0,"Faltan","Sobran"))) -> Correcto | L41: =IF(ISBLANK(J41)," ",IF(ABS(J41-I41)<0.01," ",J41-I41)) | N41: 26 de diciembre | O41: 1
C42: 45992 | D42: 2166.6667 | E42: =(D42+G42)*0.0483 -> 104.65 | F42: =(D42+G42)*0.0165 -> 35.75 | H42: =D42*$N$36 -> 281.66667 | I42: =D42-E42-H42-F42-G42 -> 1744.6 | J42: 1744.6 | K42: =IF(ISBLANK(J42)," ",IF(ABS(J42-I42)<0.01,"Correcto ",IF(J42-I42<0,"Faltan","Sobran"))) -> Correcto | L42: =IF(ISBLANK(J42)," ",IF(ABS(J42-I42)<0.01," ",J42-I42)) | N42: 29 30 diciembre | O42: 2
K43: =IF(ISBLANK(J43)," ",IF(ABS(J43-I43)<0.01,"Correcto ",IF(J43-I43<0,"Faltan","Sobran"))) | L43: =IF(ISBLANK(J43)," ",IF(J43-I43<0.01," ",J43-I43))
K44: =IF(ISBLANK(J44)," ",IF(ABS(J44-I44)<0.01,"Correcto ",IF(J44-I44<0,"Faltan","Sobran"))) | L44: =IF(ISBLANK(J44)," ",IF(J44-I44<0.01," ",J44-I44)) | N44: Disfrutadas | O44: =SUM(O40:O43) -> 7
D45: =SUM(D30:D44) -> 8666.6629 | E45: =SUM(E30:E44) -> 418.59982 | F45: =SUM(F30:F44) -> 142.99994 | G45: =SUM(G30:G44) -> 0 | H45: =SUM(H30:H44) -> 1126.6662 | I45: =SUM(I30:I44) -> 6978.3969 | J45: =SUM(J30:J44) -> 6978.39 | N45: =+IF(O44<O39,"Por coger",IF(O44>O39,"Del año que viene"," ")) -> Por coger
D46: =D45-E45-H45-F45-G45 -> 6978.3969

Sheet Intereses cuentas
C2: EVO | H2: Banc Sabadell | M2: N26 | R2: Bruto | S2: TOTAL
C3: Intereses | D3: Retención | E3: Neto | F3: Ingresado | H3: Intereses | I3: Retención | J3: Neto | K3: Ingresado | M3: Intereses | N3: Retención | O3: Neto | P3: Ingresado
A4: 2023 | B4: 45139 | C4: 21.3 | D4: =C4*0.19 -> 4.047 | E4: =C4-D4 -> 17.253 | F4: 17.25 | R4: =+C4+H4+M4 -> 21.3 | S4: =SUM(E4,J4,O4) -> 17.253 | U4: =F4+K4+P4 -> 17.25 | Y4: 2023 | Z4: Intereses | AA4: =SUM(C4:C8,H4:H8,M4:M8) -> 566.45481
B5: 45170 | C5: 63.703704 | D5: =C5*0.19 -> 12.103704 | E5: =C5-D5 -> 51.6 | F5: 51.6 | R5: =+C5+H5+M5 -> 63.703704 | S5: =SUM(E5,J5,O5) -> 51.6 | U5: =F5+K5+P5 -> 51.6 | Z5: Retención | AA5: =SUM(D4:D8,I4:I8,N4:N8) -> 107.62641 | AB5: =+AA4-AA5 -> 458.8284
B6: 45200 | C6: 61.641975 | D6: =C6*0.19 -> 11.711975 | E6: =C6-D6 -> 49.93 | F6: 49.93 | H6: 26.71 | I6: =H6*0.19 -> 5.0749 | J6: =H6-I6 -> 21.6351 | K6: 21.64 | M6: 26.01 | N6: =M6*0.19 -> 4.9419 | O6: =M6-N6 -> 21.0681 | P6: 21.07 | R6: =+C6+H6+M6 -> 114.36198 | S6: =SUM(E6,J6,O6) -> 92.6332 | U6: =F6+K6+P6 -> 92.64
B7: 45231 | C7: 61.643836 | D7: =C7*0.19 -> 11.712329 | E7: =C7-D7 -> 49.931507 | F7: 49.93 | H7: 63.7 | I7: =H7*0.19 -> 12.103 | J7: =H7-I7 -> 51.597 | K7: 51.6 | M7: =29000*0.0226/12 -> 54.616667 | N7: =M7*0.19 -> 10.377167 | O7: =M7-N7 -> 44.2395 | P7: 45.08 | R7: =+C7+H7+M7 -> 179.9605 | S7: =SUM(E7,J7,O7) -> 145.76801 | U7: =F7+K7+P7 -> 146.61
B8: 45261 | C8: 63.69863 | D8: =C8*0.19 -> 12.10274 | E8: =C8-D8 -> 51.59589 | F8: 51.6 | H8: 61.64 | I8: =H8*0.19 -> 11.7116 | J8: =H8-I8 -> 49.9284 | K8: 49.93 | M8: 61.79 | N8: =M8*0.19 -> 11.7401 | O8: =M8-N8 -> 50.0499 | P8: 50.05 | R8: =+C8+H8+M8 -> 187.12863 | S8: =SUM(E8,J8,O8) -> 151.57419 | T8: =SUM(S4:S8) -> 458.8284 | U8: =F8+K8+P8 -> 151.58 | V8: =SUM(U4:U8) -> 459.68
C10: EVO | H10: Banc Sabadell | M10: N26 | Y10: 2024 | Z10: Intereses | AA10: =SUM(C12:C19,H12:H19,M12:M23) -> 3132.2744
C11: Intereses | D11: Retención | E11: Neto | F11: Ingresado | H11: Intereses | I11: Retención | J11: Neto | K11: Ingresado | M11: Intereses | N11: Retención | O11: Neto | P11: Ingresado | Z11: Retención | AA11: =SUM(D12:D19,I12:I19,N12:N23) -> 595.13214 | AB11: =+AA10-AA11 -> 2537.1423
A12: 2024 | B12: 45292 | C12: 63.63 | D12: =C12*0.19 -> 12.0897 | E12: =C12-D12 -> 51.5403 | F12: 51.54 | H12: 63.7 | I12: =H12*0.19 -> 12.103 | J12: =H12-I12 -> 51.597 | K12: 51.6 | M12: 67.06 | N12: =M12*0.19 -> 12.7414 | O12: =M12-N12 -> 54.3186 | P12: 54.32 | R12: =+C12+H12+M12 -> 194.39 | S12: =SUM(E12,J12,O12) -> 157.4559 | U12: =F12+K12+P12 -> 157.46
B13: 45323 | C13: 59.432099 | D13: =C13*0.19 -> 11.292099 | E13: =C13-D13 -> 48.14 | F13: 48.14 | H13: 63.7 | I13: =H13*0.19 -> 12.103 | J13: =H13-I13 -> 51.597 | K13: 51.6 | M13: 66.14 | N13: =M13*0.19 -> 12.5666 | O13: =M13-N13 -> 53.5734 | P13: 53.57 | R13: =+C13+H13+M13 -> 189.2721 | S13: =SUM(E13,J13,O13) -> 153.3104 | U13: =F13+K13+P13 -> 153.31
B14: 45352 | C14: 63.518519 | D14: =C14*0.19 -> 12.068519 | E14: =C14-D14 -> 51.45 | F14: 51.45 | H14: 59.59 | I14: =H14*0.19 -> 11.3221 | J14: =H14-I14 -> 48.2679 | K14: 48.27 | M14: 50.567901 | N14: =M14*0.19 -> 9.6079012 | O14: =M14-N14 -> 40.96 | P14: =20.96+20 -> 40.96 | R14: =+C14+H14+M14 -> 173.67642 | S14: =SUM(E14,J14,O14) -> 140.6779 | U14: =F14+K14+P14 -> 140.68
B15: 45383 | C15: 61.481481 | D15: =C15*0.19 -> 11.681481 | E15: =C15-D15 -> 49.8 | F15: 49.8 | H15: 63.7 | I15: =H15*0.19 -> 12.103 | J15: =H15-I15 -> 51.597 | K15: 51.6 | M15: 78.36 | N15: =M15*0.19 -> 14.8884 | O15: =M15-N15 -> 63.4716 | P15: 63.47 | R15: =+C15+H15+M15 -> 203.54148 | S15: =SUM(E15,J15,O15) -> 164.8686 | U15: =F15+K15+P15 -> 164.87 | Y15: 2025 | Z15: Intereses | AA15: =SUM(M27:M29,H27:H30,C27:C38)+C42+40 -> 3348.6303
B16: 45413 | C16: 63.518519 | D16: =C16*0.19 -> 12.068519 | E16: =C16-D16 -> 51.45 | F16: 51.45 | H16: 61.64 | I16: =H16*0.19 -> 11.7116 | J16: =H16-I16 -> 49.9284 | K16: 49.93 | M16: 82.91358 | N16: =M16*0.19 -> 15.75358 | O16: =M16-N16 -> 67.16 | P16: 67.16 | R16: =+C16+H16+M16 -> 208.0721 | S16: =SUM(E16,J16,O16) -> 168.5384 | U16: =F16+K16+P16 -> 168.54 | Z16: Retención | AA16: =SUM(N27:N29,I27:I30,D27:D38)+D42+40*19% -> 636.23426 | AB16: =+AA15-AA16 -> 2712.396
B17: 45444 | C17: 10.654321 | D17: =C17*0.19 -> 2.024321 | E17: =C17-D17 -> 8.63 | F17: 8.63 | H17: 63.7 | I17: =H17*0.19 -> 12.103 | J17: =H17-I17 -> 51.597 | K17: 51.6 | M17: 72.925926 | N17: =M17*0.19 -> 13.855926 | O17: =M17-N17 -> 59.07 | P17: 59.07 | R17: =+C17+H17+M17 -> 147.28025 | S17: =SUM(E17,J17,O17) -> 119.297 | U17: =F17+K17+P17 -> 119.3
B18: 45474 | H18: 10.27 | I18: =H18*0.19 -> 1.9513 | J18: =H18-I18 -> 8.3187 | K18: 8.32 | M18: 284.92593 | N18: =M18*0.19 -> 54.135926 | O18: =M18-N18 -> 230.79 | P18: 230.79 | R18: =+C18+H18+M18 -> 295.19593 | S18: =SUM(E18,J18,O18) -> 239.1087 | U18: =K18+P18 -> 239.11
B19: 45505 | M19: 369.50617 | N19: =M19*0.19 -> 70.206173 | O19: =M19-N19 -> 299.3 | P19: 299.3 | R19: =+C19+H19+M19 -> 369.50617 | S19: =SUM(E19,J19,O19) -> 299.3 | U19: =P19 -> 299.3
B20: 45536 | M20: 381.18 | N20: =M20*0.19 -> 72.4242 | O20: =M20-N20 -> 308.7558 | P20: 308.76 | R20: =+C20+H20+M20 -> 381.18 | S20: =SUM(E20,J20,O20) -> 308.7558 | U20: =+P20 -> 308.76 | Y20: 2026 | Z20: Intereses | AA20: =SUM(C43:C54)+20 -> 3560.1437
B21: 45566 | M21: 373.57 | N21: =M21*0.19 -> 70.9783 | O21: =M21-N21 -> 302.5917 | P21: 302.59 | R21: =+C21+H21+M21 -> 373.57 | S21: =SUM(E21,J21,O21) -> 302.5917 | U21: =P21 -> 302.59 | Z21: Retención | AA21: =SUM(D43:D54)+20*0.19 -> 676.4273 | AB21: =+AA20-AA21 -> 2883.7164
B22: 45597 | H22: =SUM(H4:H21) -> 538.35 | I22: =SUM(I5:I21) -> 102.2865 | J22: =SUM(J5:J21) -> 436.0635 | K22: =SUM(K6:K21) -> 436.09 | M22: =294.37 -> 294.37 | N22: =M22*0.19 -> 55.9303 | O22: =M22-N22 -> 238.4397 | P22: 238.44 | R22: =+M22 -> 294.37 | S22: =SUM(,O22) -> 238.4397 | U22: =P22 -> 238.44
B23: 45627 | M23: 302.22 | N23: =M23*0.19 -> 57.4218 | O23: =M23-N23 -> 244.7982 | P23: 244.8 | R23: =+C23+H23+M23 -> 302.22 | S23: =SUM(E23,J23,O23) -> 244.7982 | T23: =SUM(S12:S23) -> 2537.1423 | U23: =+P23 -> 244.8 | V23: =SUM(U12:U23) -> 2537.16
C25: Bankinter | H25: B100 | M25: N26
C26: Intereses | D26: Retención | E26: Neto | F26: Ingresado | H26: Intereses | I26: Retención | J26: Neto | K26: Ingresado | M26: Intereses | N26: Retención | O26: Neto | P26: Ingresado
A27: 2025 | B27: 45658 | H27: 36.58 | I27: =+H27*0.19 -> 6.9502 | J27: =H27-I27 -> 29.6298 | K27: 29.63 | M27: 319.85 | N27: =M27*0.19 -> 60.7715 | O27: =+M27-N27 -> 259.0785 | P27: 259.08 | R27: =+C27+H27+M27 -> 356.43 | S27: =SUM(E27,J27,O27) -> 288.7083 | U27: =P27+K27 -> 288.71 | AB27: bruto | AC27: retencion
B28: 45689 | H28: 102.41 | I28: =+H28*0.19 -> 19.4579 | J28: =H28-I28 -> 82.9521 | K28: 82.95 | M28: =((128000-50000)*0.025/12/30*23)+(128000*0.028/12/30*7) -> 194.27222 | N28: =M28*0.19 -> 36.911722 | O28: =+M28-N28 -> 157.3605 | P28: 160.19 | R28: =+C28+H28+M28 -> 296.68222 | S28: =SUM(E28,J28,O28) -> 240.3126 | U28: =P28+K28 -> 243.14 | AA28: n26 | AB28: 541.57 | AC28: 102.89
B29: 45717 | C29: 161.65432 | D29: =+C29*0.19 -> 30.714321 | E29: =+C29-D29 -> 130.94 | F29: =119.29+11.65 -> 130.94 | H29: 102.41 | I29: =+H29*0.19 -> 19.4579 | J29: =H29-I29 -> 82.9521 | K29: 82.95 | M29: 27.45 | N29: 5.21 | O29: =+M29-N29 -> 22.24 | P29: 19.41 | R29: =+C29+H29+M29 -> 291.51432 | S29: =SUM(E29,J29,O29) -> 236.1321 | U29: =P29+K29+F29 -> 233.3 | AA29: bankinter | AB29: 2164.51 | AC29: 411.19
B30: 45748 | C30: =118840*0.0247/12 -> 244.61233 | D30: =+C30*0.19 -> 46.476343 | E30: =+C30-D30 -> 198.13599 | F30: 198.14 | H30: 14.28 | I30: =+H30*0.19 -> 2.7132 | J30: =H30-I30 -> 11.5668 | K30: 11.57 | R30: =+C30+H30 -> 258.89233 | S30: =SUM(E30,J30) -> 209.70279 | U30: =K30+F30 -> 209.71 | AA30: openbank | AB30: =+C42 -> 338.13 | AC30: =+D42 -> 64.2447
B31: 45778 | C31: 272.49 | D31: =+C31*0.19 -> 51.7731 | E31: =+C31-D31 -> 220.7169 | F31: 220.72 | R31: =+C31+H31 -> 272.49 | S31: =SUM(E31,J31) -> 220.7169 | U31: =F31 -> 220.72 | AA31: b100 | AB31: =+H33 -> 255.68 | AC31: =+I33 -> 48.5792
B32: 45809 | C32: 285.82 | D32: =+C32*0.19 -> 54.3058 | E32: =+C32-D32 -> 231.5142 | F32: 231.51 | R32: =+C32 -> 285.82 | S32: =SUM(E32,J32) -> 231.5142 | U32: =F32 -> 231.51 | AB32: =SUM(AB28:AB31) -> 3299.89 | AC32: =SUM(AC28:AC31) -> 626.9039
B33: 45839 | C33: 251.64198 | D33: =+C33*0.19 -> 47.811975 | E33: =+C33-D33 -> 203.83 | F33: 203.83 | H33: =SUM(H27:H31) -> 255.68 | I33: =SUM(I27:I31) -> 48.5792 | J33: =SUM(J27:J31) -> 207.1008 | K33: =SUM(K27:K31) -> 207.1 | M33: =+SUM(M4:M8,M12:M23,M27:M30) -> 3107.7284 | N33: =+SUM(N4:N8,N12:N23,N27:N30) -> 590.4629 | O33: =+SUM(O4:O8,O12:O23,O27:O30) -> 2517.2655 | P33: =+SUM(P4:P8,P12:P23,P27:P30) -> 2518.11 | R33: =+C33 -> 251.64198 | S33: =SUM(E33) -> 203.83 | U33: =F33 -> 203.83
B34: 45870 | C34: 231.55556 | D34: =+C34*0.19 -> 43.995556 | E34: =+C34-D34 -> 187.56 | F34: 187.56 | R34: =+C34 -> 231.55556 | S34: =SUM(E34) -> 187.56 | U34: =P34+K34+F34 -> 187.56
B35: 45901 | C35: 231.55556 | D35: =+C35*0.19 -> 43.995556 | E35: =+C35-D35 -> 187.56 | F35: 187.58 | R35: =+C35 -> 231.55556 | S35: =SUM(E35) -> 187.56 | U35: =P35+K35+F35 -> 187.58
B36: 45931 | C36: =(137000/30*23+138000/31*8)*0.0199/12 -> 233.23834 | D36: =+C36*0.19 -> 44.315285 | E36: =+C36-D36 -> 188.92306 | F36: 181.88 | R36: =+C36 -> 233.23834 | S36: =SUM(E36) -> 188.92306 | U36: =P36+K36+F36 -> 181.88
B37: 45962 | C37: 233.73 | D37: =+C37*0.19 -> 44.4087 | E37: =+C37-D37 -> 189.3213 | F37: 189.33 | R37: =+C37 -> 233.73 | S37: =SUM(E37) -> 189.3213 | U37: =F37 -> 189.33
B38: 45992 | C38: 26.95 | D38: =+C38*0.19 -> 5.1205 | E38: =+C38-D38 -> 21.8295 | F38: 21.83 | R38: =+C42+C38 -> 365.08 | S38: =SUM(E38,E42) -> 295.7148 | T38: =SUM(S27:S38) -> 2679.996 | U38: =F38+F42 -> 295.72 | V38: =SUM(U27:U38) -> 2672.99
C40: Openbank / Trade Republic / Cajamar
C41: Intereses | D41: Retención | E41: Neto | F41: Ingresado
A42: 2026 | B42: 45992 | C42: 338.13 | D42: =+C42*0.19 -> 64.2447 | E42: =+C42-D42 -> 273.8853 | F42: 273.89 | R42: =+C43 -> 362.407 | S42: =SUM(E43) -> 293.54967 | U42: =F42 -> 273.89
B43: 46023 | C43: =362.407 -> 362.407 | D43: =+C43*0.19 -> 68.85733 | E43: =+C43-D43 -> 293.54967 | F43: 293.55 | R43: =+C44 -> 371.6 | S43: =SUM(E44) -> 300.996 | U43: =F43 -> 293.55
B44: 46054 | C44: 371.6 | D44: =+C44*0.19 -> 70.604 | E44: =+C44-D44 -> 300.996 | F44: 301 | R44: =+C45 -> 344.75 | S44: =SUM(E45) -> 279.2475 | U44: =F44 -> 301
...

Sheet IRPF
B1: RENTA 202 | F1: CUOTA ÍNTEGRA | M1: RENTA 202 | Q1: CUOTA ÍNTEGRA
F2: Resultado de la escala general | J2: =4158+(E14-18080)*0.28 -> -5671.4112 | Q2: Resultado de la escala general | U2: =4158+(P14-18080)*0.28 -> -5671.4112
F3: Minoración | J3: =1615 -> 1615 | Q3: Minoración | U3: =1615 -> 1615
B4: RENTA GENERAL | F4: Cuota íntegra general | J4: =J2-J3 -> -7286.4112 | M4: RENTA GENERAL | Q4: Cuota íntegra general | U4: =U2-U3 -> -7286.4112
B5: Rendimientos del Trabajo | F5: Cuota íntegra del ahorro | J5: =0.19*E21 -> 0 | M5: Rendimientos del Trabajo | Q5: Cuota íntegra del ahorro | U5: =0.2*P22 -> 0
B6: Rendimientos íntegros | M6: Rendimientos íntegros
B7: Gastos deducibles | F7: Total cuota | J7: =J4+J5 -> -7286.4112 | M7: Gastos deducibles | Q7: Total cuota | U7: =U4 -> -7286.4112
B8: Bonificación | E8: =8000-(E6-E7-14800)*0.6098 -> 17025.04 | F8: DEDUCCIONES | M8: Bonificación | P8: =8000-(P6-P7-14800)*0.6098 -> 17025.04 | Q8: DEDUCCIONES
B9: Rendimiento neto del trabajo | E9: =E6-E7-E8 -> -17025.04 | F9: Edad | M9: Rendimiento neto del trabajo | P9: =P6-P7-P8 -> -17025.04 | Q9: Edad
B10: Ganancia patrimonial | F10: Actividades mecenazgo (donativos) | J10: 0 | M10: Ganancia patrimonial | Q10: Actividades mecenazgo (donativos) | U10: 0
B12: TOTAL RENTAS BASE IMPONIBLE GRAL. | E12: =E9 -> -17025.04 | F12: Total deducciones | J12: =J9+J10 -> 0 | M12: TOTAL RENTAS BASE IMPONIBLE GRAL. | P12: =P9 -> -17025.04 | Q12: Total deducciones | U12: =U9+U10 -> 0
F13: CUOTA LÍQUIDA | J13: =IF(J7>0,J7-J12,0) -> 0 | Q13: CUOTA LÍQUIDA | U13: =IF(U7>0,U7-U12,0) -> 0
B14: BASE IMPONIBLE GENERAL | E14: =E12 -> -17025.04 | F14: Incremento por pérdida beneficios | M14: BASE IMPONIBLE GENERAL | P14: =P12 -> -17025.04 | Q14: Incremento por pérdida beneficios
F15: PAGOS A CUENTA | Q15: PAGOS A CUENTA
B16: Capital Mobiliario | F16: Retenciones trabajo | M16: Capital Mobiliario | Q16: Retenciones trabajo
B17: Rendimiento neto capital mobiliario | F17: Retenciones capital mobiliario | M17: Rendimiento neto capital mobiliario | P17: 0 | Q17: Retenciones capital mobiliario | U17: 0
F19: Total pagos a cuenta | J19: =J16+J17 -> 0 | Q19: Total pagos a cuenta | U19: =U16+U17 -> 0
B20: Ganancia patrimonial | F20: Opción tributaria por retenciones | M20: Ganancia patrimonial | Q20: Opción tributaria por retenciones
B21: TOTAL RENTAS B.I. DEL AHORRO | E21: 0 | F21: CUOTA DIFERENCIAL | J21: =J13-J19 -> 0 | M21: TOTAL RENTAS B.I. DEL AHORRO | P21: 0 | Q21: CUOTA DIFERENCIAL | U21: =U13-U19 -> 0
B22: BASE LIQUIDABLE DEL AHORRO | E22: =E17 -> 0 | F22: =IF(J21<0,"A DEVOLVER","A INGRESAR") -> A INGRESAR | J22: =ABS(J21) -> 0 | M22: BASE LIQUIDABLE DEL AHORRO | P22: 0 | Q22: =IF(U21<0,"A DEVOLVER","A INGRESAR") -> A INGRESAR | U22: =ABS(U21) -> 0
G24: Tipo de interes | R24: Tipo de interes
G25: 17720 | H25: 4075.6 | R25: 17720 | S25: 4075.6
G26: =E14-G25 -> -34745.04 | H26: =0.28*G26 -> -9728.6112 | R26: =P14-R25 -> -34745.04 | S26: =0.28*R26 -> -9728.6112
G27: 2500 | H27: =0.2*G27 -> 500 | R27: 2500 | S27: =0.2*R27 -> 500
G28: =+E22-G27 -> -2500 | H28: =+G28*0.21 -> -525 | R28: =+P22-R27 -> -2500 | S28: =+R28*0.21 -> -525
H29: =SUM(H25:H28) -> -5678.0112 | I29: =H29/(E6+E22) -> #DIV/0! | S29: =SUM(S25:S28) -> -5678.0112 | T29: =S29/(P6+P22) -> #DIV/0!
B31: RENTA 2025 | F31: CUOTA ÍNTEGRA | M31: RENTA 2026 | Q31: CUOTA ÍNTEGRA
F32: Resultado de la escala general | J32: =+E44*0.23 -> 2956.1121 | Q32: Resultado de la escala general | U32: =4158+(P44-18080)*0.28 -> 5062.399
F33: Minoración | J33: 1583 | Q33: Minoración | U33: 1583
B34: RENTA GENERAL | F34: Cuota íntegra general | J34: =J32-J33 -> 1373.1121 | M34: RENTA GENERAL | Q34: Cuota íntegra general | U34: =U32-U33 -> 3479.399
B35: Rendimientos del Trabajo | F35: Cuota íntegra del ahorro | J35: =0.2*2500+0.21*(E47-2500) -> 679.4009 | M35: Rendimientos del Trabajo | Q35: Cuota íntegra del ahorro | U35: =0.19*P52 -> 672.6273
B36: Rendimientos íntegros | E36: 19983.6 | M36: Rendimientos íntegros | P36: =+'25 26 Vadillo'!O11 -> 25999.996
B37: Gastos deducibles | E37: 1416.51 | F37: Total cuota | J37: =J34+J35 -> 2052.513 | M37: Gastos deducibles | P37: =+'25 26 Vadillo'!O12 -> 1689.9998 | Q37: Total cuota | U37: =U34+U35 -> 4152.0263
B38: Bonificación | E38: =8000-(E36-E37-14800)*0.6098 -> 5702.8285 | F38: DEDUCCIONES | M38: Bonificación | P38: 3000 | Q38: DEDUCCIONES
B39: Rendimiento neto del trabajo | E39: =E36-E37-E38 -> 12864.261 | F39: Edad | M39: Rendimiento neto del trabajo | P39: =P36-P37-P38 -> 21309.996 | Q39: Edad
B40: Ganancia patrimonial | F40: Actividades mecenazgo (donativos) | J40: 0 | M40: Ganancia patrimonial | Q40: Actividades mecenazgo (donativos) | U40: 0
B42: TOTAL RENTAS BASE IMPONIBLE GRAL. | E42: =E39-11.6 -> 12852.661 | F42: Total deducciones | J42: 0.58 | M42: TOTAL RENTAS BASE IMPONIBLE GRAL. | P42: =P39 -> 21309.996 | Q42: Total deducciones | U42: =U39+U40 -> 0
F43: CUOTA LÍQUIDA | J43: =IF(J37>0,J37-J42,0) -> 2051.933 | Q43: CUOTA LÍQUIDA | U43: =IF(U37>0,U37-U42,0) -> 4152.0263
B44: BASE IMPONIBLE GENERAL | E44: =E42 -> 12852.661 | F44: Incremento por pérdida beneficios | M44: BASE IMPONIBLE GENERAL | P44: =P42 -> 21309.996 | Q44: Incremento por pérdida beneficios
F45: PAGOS A CUENTA | Q45: PAGOS A CUENTA
...

Sheet 25 Eurocybcar
C2: Eurocybcar
C5: TOTAL | D5: =+J25 -> 2327.33
D9: Bruto | E9: SS | F9: Desemp | G9: EPSV | H9: IRPF | I9: Sueldo | J9: Ingresado | K9: Diferencia | M9: Paga Extra | R9: 2025
B10: 2025 | C10: 45658 | I10: =D10-E10-H10-F10 -> 0 | K10: =IF(ISBLANK(J10)," ",IF(J10-I10<0.01,"Correcto ",IF(J10-I10<0.01,"Faltan","Sobran"))) | L10: =IF(ISBLANK(J10)," ",IF(ABS(J10-I10)<0.01," ",J10-I10)) | R10: 44562 | S10: L | T10: M | U10: X | V10: J | W10: V | X10: S | Y10: D | Z10: L | AA10: M | AB10: X | AC10: J | AD10: V | AE10: S | AF10: D | AG10: L | AH10: M | AI10: X | AJ10: J | AK10: V | AL10: S | AM10: D | AN10: L | AO10: M | AP10: X | AQ10: J | AR10: V | AS10: S | AT10: D | AU10: L | AV10: M | AW10: X | AX10: J | AY10: V | AZ10: S | BA10: D | BB10: L | BC10: M
C11: 45689 | I11: =D11-E11-H11-F11 -> 0 | K11: =IF(ISBLANK(J11)," ",IF(J11-I11<0.01,"Correcto ",IF(J11-I11<0.01,"Faltan","Sobran"))) | L11: =IF(ISBLANK(J11)," ",IF(ABS(J11-I11)<0.01," ",J11-I11)) | R11: MAY | Z11: 5 | AA11: 6 | AB11: 7 | AC11: 8 | AD11: 9 | AE11: 10 | AF11: 11 | AG11: 12 | AH11: 13 | AI11: 14 | AJ11: 15 | AK11: 16 | AL11: 17 | AM11: 18 | AN11: 19 | AO11: 20 | AP11: 21 | AQ11: 22 | AR11: 23 | AS11: 24 | AT11: 25 | AU11: 26 | AV11: 27 | AW11: 28 | AX11: 29 | AY11: 30 | AZ11: 31
C12: 45717 | I12: =D12-E12-H12-F12 -> 0 | K12: =IF(ISBLANK(J12)," ",IF(J12-I12<0.01,"Correcto ",IF(J12-I12<0.01,"Faltan","Sobran"))) | L12: =IF(ISBLANK(J12)," ",IF(ABS(J12-I12)<0.01," ",J12-I12)) | R12: JUN | Y12: 1 | Z12: 2 | AA12: 3 | AB12: 4 | AC12: 5 | AD12: 6 | AE12: 7 | AF12: 8 | AG12: 9 | AH12: 10 | AI12: 11 | AJ12: 12 | AK12: 13
C13: 45748 | I13: =D13-E13-H13-F13 -> 0 | K13: =IF(ISBLANK(J13)," ",IF(J13-I13<0.01,"Correcto ",IF(J13-I13<0.01,"Faltan","Sobran"))) | L13: =IF(ISBLANK(J13)," ",IF(ABS(J13-I13)<0.01," ",J13-I13)) | O13: Rend trabajo 2025 | P13: =SUM(D10:D23) -> 2898.1892
C14: 45778 | D14: =27*(49.95+1.18+4.1623+5.8273) -> 1650.2292 | E14: =(D14+M14+G14)*0.0483 -> 90.74407 | F14: =(D14+M14+G14)*0.0165 -> 30.999527 | G14: =(D14+M14)*0.2/100 -> 3.7500184 | H14: =D14*$O$16 -> 214.5298 | I14: =D14-E14-H14-F14-G14 -> 1310.2058 | J14: 1310.21 | K14: =IF(ISBLANK(J14)," ",IF(J14-I14<0.01,"Correcto ",IF(J14-I14<0.01,"Faltan","Sobran"))) -> Correcto | L14: =IF(ISBLANK(J14)," ",IF(ABS(J14-I14)<0.01," ",J14-I14)) | M14: 224.78 | O14: Gastos Deducibles SS | P14: =SUM(E10:F23) -> 188.3036
C15: 45821 | D15: =794.56+331.16+122.24 -> 1247.96 | E15: =49.61+16.95 -> 66.56 | G15: 2.05 | H15: =1247.96*0.13 -> 162.2348 | I15: =D15-E15-H15-F15-G15 -> 1017.1152 | J15: 1017.12 | K15: =IF(ISBLANK(J15)," ",IF(ABS(J15-I15)<0.01,"Correcto ",IF(J15-I15<0,"Faltan","Sobran"))) -> Correcto | L15: =IF(ISBLANK(J15)," ",IF(ABS(J15-I15)<0.01," ",J15-I15)) | O15: IRPF | P15: =SUM(H10:H23) -> 376.7646
C16: Extra JUL25 | H16: =D16*$O$16 -> 0 | I16: =D16-E16-H16-F16-G16 -> 0 | K16: =IF(ISBLANK(J16)," ",IF(ABS(J16-I16)<0.01,"Correcto ",IF(J16-I16<0,"Faltan","Sobran"))) | L16: =IF(ISBLANK(J16)," ",IF(ABS(J16-I16)<0.01," ",J16-I16)) | O16: 0.13
C17: 45839 | E17: =(D17+M17+G17)*0.0483 -> 0 | F17: =(D17+M17+G17)*0.0165 -> 0 | G17: =(D17+M17)*0.2/100 -> 0 | H17: =D17*$O$16 -> 0 | I17: =D17-E17-H17-F17-G17 -> 0 | K17: =IF(ISBLANK(J17)," ",IF(ABS(J17-I17)<0.01,"Correcto ",IF(J17-I17<0,"Faltan","Sobran"))) | L17: =IF(ISBLANK(J17)," ",IF(ABS(J17-I17)<0.01," ",J17-I17))
C18: 45870 | E18: =(D18+M18+G18)*0.0483 -> 0 | F18: =(D18+M18+G18)*0.0165 -> 0 | G18: =(D18+M18)*0.2/100 -> 0 | H18: =D18*$O$16 -> 0 | I18: =D18-E18-H18-F18-G18 -> 0 | K18: =IF(ISBLANK(J18)," ",IF(ABS(J18-I18)<0.01,"Correcto ",IF(J18-I18<0,"Faltan","Sobran"))) | L18: =IF(ISBLANK(J18)," ",IF(ABS(J18-I18)<0.01," ",J18-I18))
C19: 45901 | E19: =(D19+M19+G19)*0.0483 -> 0 | F19: =(D19+M19+G19)*0.0165 -> 0 | G19: =(D19+M19)*0.2/100 -> 0 | H19: =D19*$O$16 -> 0 | I19: =D19-E19-H19-F19-G19 -> 0 | K19: =IF(ISBLANK(J19)," ",IF(ABS(J19-I19)<0.01,"Correcto ",IF(J19-I19<0,"Faltan","Sobran"))) | L19: =IF(ISBLANK(J19)," ",IF(ABS(J19-I19)<0.01," ",J19-I19)) | O19: VACACIONES | P19: =22/12*1.25 -> 2.2916667
C20: 45931 | E20: =(D20+M20+G20)*0.0483 -> 0 | F20: =(D20+M20+G20)*0.0165 -> 0 | G20: =(D20+M20)*0.2/100 -> 0 | H20: =D20*$O$16 -> 0 | I20: =D20-E20-H20-F20-G20 -> 0 | K20: =IF(ISBLANK(J20)," ",IF(ABS(J20-I20)<0.01,"Correcto ",IF(J20-I20<0,"Faltan","Sobran"))) | L20: =IF(ISBLANK(J20)," ",IF(ABS(J20-I20)<0.01," ",J20-I20)) | R20: Horas 2025
C21: 45962 | E21: =(D21+M21+G21)*0.0483 -> 0 | F21: =(D21+M21+G21)*0.0165 -> 0 | G21: =(D21+M21)*0.2/100 -> 0 | H21: =D21*$O$16 -> 0 | I21: =D21-E21-H21-F21-G21 -> 0 | K21: =IF(ISBLANK(J21)," ",IF(ABS(J21-I21)<0.01,"Correcto ",IF(J21-I21<0,"Faltan","Sobran"))) | L21: =IF(ISBLANK(J21)," ",IF(ABS(J21-I21)<0.01," ",J21-I21)) | R21: 44562 | S21: L | T21: M | U21: X | V21: J | W21: V | X21: S | Y21: D | Z21: L | AA21: M | AB21: X | AC21: J | AD21: V | AE21: S | AF21: D | AG21: L | AH21: M | AI21: X | AJ21: J | AK21: V | AL21: S | AM21: D | AN21: L | AO21: M | AP21: X | AQ21: J | AR21: V | AS21: S | AT21: D | AU21: L | AV21: M | AW21: X | AX21: J | AY21: V | AZ21: S | BA21: D | BB21: L | BC21: M
C22: 45992 | E22: =(D22+M22+G22)*0.0483 -> 0 | F22: =(D22+M22+G22)*0.0165 -> 0 | G22: =(D22+M22)*0.2/100 -> 0 | H22: =D22*$O$16 -> 0 | I22: =D22-E22-H22-F22-G22 -> 0 | K22: =IF(ISBLANK(J22)," ",IF(ABS(J22-I22)<0.01,"Correcto ",IF(J22-I22<0,"Faltan","Sobran"))) | L22: =IF(ISBLANK(J22)," ",IF(ABS(J22-I22)<0.01," ",J22-I22)) | R22: MAY | Z22: 8.5 | AA22: 8.5 | AB22: 8.5 | AC22: 8.5 | AD22: 6 | AG22: 8.5 | AH22: 8.5 | AI22: 8.5 | AJ22: 8.5 | AK22: 6 | AN22: 8.5 | AO22: 8.5 | AP22: 8.5 | AQ22: 8.5 | AR22: 6 | AU22: 8.5 | AV22: 8.5 | AW22: 8.5 | AX22: 8.5 | AY22: 6 | BD22: =SUM(S22:BC22) -> 160
C23: Extra DIC25 | H23: =D23*$O$16 -> 0 | I23: =D23-E23-H23-F23-G23 -> 0 | K23: =IF(ISBLANK(J23)," ",IF(ABS(J23-I23)<0.01,"Correcto ",IF(J23-I23<0,"Faltan","Sobran"))) | L23: =IF(ISBLANK(J23)," ",IF(J23-I23<0.01," ",J23-I23)) | R23: JUN | Z23: 8.5 | AA23: 8.5 | AB23: 8.5 | AC23: 8.5 | AD23: 6 | AG23: 8.5 | AH23: 8.5 | AI23: 8.5 | AJ23: 8.5 | AK23: 6 | BB23: 7 | BD23: =SUM(S23:BC23) -> 87
C24: Bonus | E24: =(D24+M24)*0.0483 -> 0 | F24: =(D24+M24)*0.0165 -> 0 | G24: =(D24+M24)*0.2/100 -> 0 | H24: =D24*$O$16 -> 0 | I24: =D24-E24-H24-F24-G24 -> 0 | K24: =IF(ISBLANK(J24)," ",IF(ABS(J24-I24)<0.01,"Correcto ",IF(J24-I24<0,"Faltan","Sobran"))) | L24: =IF(ISBLANK(J24)," ",IF(J24-I24<0.01," ",J24-I24)) | O24: Disfrutadas | P24: =SUM(P20:P23) -> 0 | BD24: =SUM(BD22:BD23) -> 247
D25: =SUM(D10:D24) -> 2898.1892 | E25: =SUM(E10:E24) -> 157.30407 | F25: =SUM(F10:F24) -> 30.999527 | G25: =SUM(G10:G24) -> 5.8000184 | H25: =SUM(H10:H24) -> 376.7646 | I25: =SUM(I10:I24) -> 2327.321 | J25: =SUM(J10:J24) -> 2327.33 | O25: =+IF(P24<P19,"Por coger",IF(P24>P19,"Del año que viene"," ")) -> Por coger | P25: =ABS(P24-P19) -> 2.2916667
D26: =D25-E25-H25-F25-G25 -> 2327.321

Sheet 22 25 FarmaConsulting
C2: FarmaConsulting
C5: TOTAL | D5: =I100+I76+I50+I25 -> 61006.36
N7: Liquidación
N8: P extra | O8: =+L10+L12 -> 487.35432
D9: Bruto | E9: SS | F9: Desemp | G9: IRPF | H9: Sueldo | I9: Ingresado | J9: Diferencia | L9: Paga Extra | N9: Vacaciones | O9: =9.55*25500/365 -> 667.19178 | Q9: 2025
B10: 2025 | C10: 45658 | D10: 1821.51 | E10: =(D10+L10)*0.0483 -> 102.64185 | F10: =(D10+L10)*0.0165 -> 35.063985 | G10: =D10*0.13 -> 236.7963 | H10: =D10-E10-G10-F10 -> 1447.0079 | I10: 1447.01 | J10: =IF(ISBLANK(I10)," ",IF(I10-H10<0.01,"Correcto ",IF(I10-H10<0.01,"Faltan","Sobran"))) -> Correcto | K10: =IF(ISBLANK(I10)," ",IF(ABS(I10-H10)<0.01," ",I10-H10)) | L10: =303.58 -> 303.58 | O10: =SUM(O8:O9) -> 1154.5461 | Q10: 44562 | R10: L | S10: M | T10: X | U10: J | V10: V | W10: S | X10: D | Y10: L | Z10: M | AA10: X | AB10: J | AC10: V | AD10: S | AE10: D | AF10: L | AG10: M | AH10: X | AI10: J | AJ10: V | AK10: S | AL10: D | AM10: L | AN10: M | AO10: X | AP10: J | AQ10: V | AR10: S | AS10: D | AT10: L | AU10: M | AV10: X | AW10: J | AX10: V | AY10: S | AZ10: D | BA10: L | BB10: M
C11: Bonus | D11: 1160.16 | E11: =(D11+L11)*0.0483 -> 56.035728 | F11: =(D11+L11)*0.0165 -> 19.14264 | G11: =D11*0.13 -> 150.8208 | H11: =D11-E11-G11-F11 -> 934.16083 | I11: 934.2 | J11: =IF(ISBLANK(I11)," ",IF(I11-H11<0.01,"Correcto ",IF(I11-H11<0.01,"Faltan","Sobran"))) -> Sobran | K11: =IF(ISBLANK(I11)," ",IF(ABS(I11-H11)<0.01," ",I11-H11)) -> 0.039168 | Q11: ENE | T11: 1 | U11: 2 | V11: 3 | W11: 4 | X11: 5 | Y11: 6 | Z11: 7 | AA11: 8 | AB11: 9 | AC11: 10 | AD11: 11 | AE11: 12 | AF11: 13 | AG11: 14 | AH11: 15 | AI11: 16 | AJ11: 17 | AK11: 18 | AL11: 19 | AM11: 20 | AN11: 21 | AO11: 22 | AP11: 23 | AQ11: 24 | AR11: 25 | AS11: 26 | AT11: 27 | AU11: 28 | AV11: 29 | AW11: 30 | AX11: 31
C12: 45689 | D12: 1170.3 | E12: =2125.19*0.0483 -> 102.64668 | F12: =2125.19*0.0165 -> 35.065635 | G12: =1170.3*$N$41 -> 163.842 | H12: =D12-E12-G12-F12 -> 868.74569 | I12: 868.74 | J12: =IF(ISBLANK(I12)," ",IF(I12-H12<0.01,"Correcto ",IF(I12-H12<0.01,"Faltan","Sobran"))) -> Correcto | K12: =IF(ISBLANK(I12)," ",IF(ABS(I12-H12)<0.01," ",I12-H12)) | L12: =+'feb mar 25 baja'!F10 -> 183.77432 | Q12: FEB | W12: 1 | X12: 2 | Y12: 3 | Z12: 4 | AA12: 5 | AB12: 6 | AC12: 7 | AD12: 8 | AE12: 9 | AF12: 10 | AG12: 11 | AH12: 12 | AI12: 13 | AJ12: 14 | AK12: 15 | AL12: 16 | AM12: 17 | AN12: 18 | AO12: 19 | AP12: 20 | AQ12: 21 | AR12: 22 | AS12: 23 | AT12: 24 | AU12: 25 | AV12: 26 | AW12: 27 | AX12: 28
C13: 45717 | D13: =1647.03 -> 1647.03 | E13: =2125.19*0.0483 -> 102.64668 | F13: =2125.19*0.0165 -> 35.065635 | G13: =D13*$N$41 -> 230.5842 | H13: =D13-E13-G13-F13 -> 1278.7335 | I13: 1278.73 | J13: =IF(ISBLANK(I13)," ",IF(I13-H13<0.01,"Correcto ",IF(I13-H13<0.01,"Faltan","Sobran"))) -> Correcto | K13: =IF(ISBLANK(I13)," ",IF(ABS(I13-H13)<0.01," ",I13-H13)) | N13: Rend trabajo 2024 | O13: =SUM(D10:D24) -> 8653.7061 | Q13: MAR | W13: 1 | X13: 2 | Y13: 3 | Z13: 4 | AA13: 5 | AB13: 6 | AC13: 7 | AD13: 8 | AE13: 9 | AF13: 10 | AG13: 11 | AH13: 12 | AI13: 13 | AJ13: 14 | AK13: 15 | AL13: 16 | AM13: 17 | AN13: 18 | AO13: 19 | AP13: 20 | AQ13: 21 | AR13: 22 | AS13: 23 | AT13: 24 | AU13: 25 | AV13: 26 | AW13: 27 | AX13: 28 | AY13: 29 | AZ13: 30 | BA13: 31
C14: 45748 | D14: =53.13*30 -> 1593.9 | E14: =2125.19*0.0483 -> 102.64668 | F14: =2125.19*0.0165 -> 35.065635 | G14: =+(D14+L10+L12)*14% -> 291.37561 | H14: =D14-E14-G14-F14 -> 1164.8121 | I14: 1164.81 | J14: =IF(ISBLANK(I14)," ",IF(I14-H14<0.01,"Correcto ",IF(I14-H14<0.01,"Faltan","Sobran"))) -> Correcto | K14: =IF(ISBLANK(I14)," ",IF(ABS(I14-H14)<0.01," ",I14-H14)) | N14: Gastos Deducibles SS | O14: =SUM(E10:F24) -> 706.21597 | Q14: ABR | S14: 1 | T14: 2 | U14: 3 | V14: 4 | W14: 5 | X14: 6 | Y14: 7 | Z14: 8 | AA14: 9 | AB14: 10 | AC14: 11 | AD14: 12 | AE14: 13 | AF14: 14 | AG14: 15 | AH14: 16 | AI14: 17 | AJ14: 18 | AK14: 19 | AL14: 20 | AM14: 21 | AN14: 22 | AO14: 23 | AP14: 24 | AQ14: 25 | AR14: 26 | AS14: 27 | AT14: 28 | AU14: 29 | AV14: 30
C15: FINIQUITO | D15: =+O10 -> 1154.5461 | E15: =(D15+L15)*0.0483 -> 55.764577 | F15: =(D15+L15)*0.0165 -> 19.050011 | G15: =D15*0.13 -> 150.09099 | H15: =D15-E15-G15-F15 -> 929.64052 | I15: 929.64 | J15: =IF(ISBLANK(I15)," ",IF(I15-H15<0.01,"Correcto ",IF(I15-H15<0.01,"Faltan","Sobran"))) -> Correcto | K15: =IF(ISBLANK(I15)," ",IF(ABS(I15-H15)<0.01," ",I15-H15)) | N15: IRPF | O15: =SUM(G10:G24) -> 1237.3199
C16: BAJA MUTUA | D16: 106.26 | E16: =(D16+L16)*0.0483 -> 5.132358 | F16: =(E16+M16)*0.0483 -> 0.24789289 | G16: 13.81 | H16: =D16-E16-G16-F16 -> 87.069749 | I16: 92.45 | J16: =IF(ISBLANK(I16)," ",IF(ABS(I16-H16)<0.01,"Correcto ",IF(ABS(I16-H16)>0.01,"Faltan","Sobran"))) -> Faltan | K16: =IF(ISBLANK(I16)," ",IF(ABS(I16-H16)<0.01," ",I16-H16)) -> 5.3802509 | N16: 0.14
H17: =D17-E17-G17-F17 -> 0 | J17: =IF(ISBLANK(I17)," ",IF(ABS(I17-H17)<0.01,"Correcto ",IF(ABS(I17-H17)>0.01,"Faltan","Sobran"))) | K17: =IF(ISBLANK(I17)," ",IF(ABS(I17-H17)<0.01," ",I17-H17))
H18: =D18-E18-G18-F18 -> 0 | J18: =IF(ISBLANK(I18)," ",IF(ABS(I18-H18)<0.01,"Correcto ",IF(ABS(I18-H18)>0.01,"Faltan","Sobran"))) | K18: =IF(ISBLANK(I18)," ",IF(ABS(I18-H18)<0.01," ",I18-H18))
H19: =D19-E19-G19-F19 -> 0 | J19: =IF(ISBLANK(I19)," ",IF(ABS(I19-H19)<0.01,"Correcto ",IF(ABS(I19-H19)>0.01,"Faltan","Sobran"))) | K19: =IF(ISBLANK(I19)," ",IF(ABS(I19-H19)<0.01," ",I19-H19)) | N19: VACACIONES | O19: 22
H20: =D20-E20-G20-F20 -> 0 | J20: =IF(ISBLANK(I20)," ",IF(ABS(I20-H20)<0.01,"Correcto ",IF(ABS(I20-H20)>0.01,"Faltan","Sobran"))) | K20: =IF(ISBLANK(I20)," ",IF(ABS(I20-H20)<0.01," ",I20-H20))
H21: =D21-E21-G21-F21 -> 0 | J21: =IF(ISBLANK(I21)," ",IF(ABS(I21-H21)<0.01,"Correcto ",IF(ABS(I21-H21)>0.01,"Faltan","Sobran"))) | K21: =IF(ISBLANK(I21)," ",IF(ABS(I21-H21)<0.01," ",I21-H21))
H22: =D22-E22-G22-F22 -> 0 | J22: =IF(ISBLANK(I22)," ",IF(ABS(I22-H22)<0.01,"Correcto ",IF(ABS(I22-H22)>0.01,"Faltan","Sobran"))) | K22: =IF(ISBLANK(I22)," ",IF(ABS(I22-H22)<0.01," ",I22-H22))
H23: =D23-E23-G23-F23 -> 0 | J23: =IF(ISBLANK(I23)," ",IF(ABS(I23-H23)<0.01,"Correcto ",IF(ABS(I23-H23)>0.01,"Faltan","Sobran"))) | K23: =IF(ISBLANK(I23)," ",IF(ABS(I23-H23)<0.01," ",I23-H23))
H24: =D24-E24-G24-F24 -> 0 | J24: =IF(ISBLANK(I24)," ",IF(ABS(I24-H24)<0.01,"Correcto ",IF(ABS(I24-H24)>0.01,"Faltan","Sobran"))) | K24: =IF(ISBLANK(I24)," ",IF(I24-H24<0.01," ",I24-H24))
D25: =SUM(D10:D24) -> 8653.7061 | E25: =SUM(E10:E24) -> 527.51454 | F25: =SUM(F10:F24) -> 178.70143 | G25: =SUM(G10:G24) -> 1237.3199 | H25: =SUM(H10:H24) -> 6710.1702 | I25: =SUM(I10:I24) -> 6715.58
D26: =D25-E25-G25-F25 -> 6710.1702
I27: 2025 | J27: 2550 | K27: Cumplimiento
